[2019-04-02 23:23:28,770] ERROR in app: Exception on /scripts/main.js [GET]
Traceback (most recent call last):
  File "/home/gray/.pyenv/versions/2.7/envs/psiturkpy/lib/python2.7/site-packages/flask/app.py", line 1982, in wsgi_app
    response = self.full_dispatch_request()
  File "/home/gray/.pyenv/versions/2.7/envs/psiturkpy/lib/python2.7/site-packages/flask/app.py", line 1614, in full_dispatch_request
    rv = self.handle_user_exception(e)
  File "/home/gray/.pyenv/versions/2.7/envs/psiturkpy/lib/python2.7/site-packages/flask/app.py", line 1517, in handle_user_exception
    reraise(exc_type, exc_value, tb)
  File "/home/gray/.pyenv/versions/2.7/envs/psiturkpy/lib/python2.7/site-packages/flask/app.py", line 1612, in full_dispatch_request
    rv = self.dispatch_request()
  File "/home/gray/.pyenv/versions/2.7/envs/psiturkpy/lib/python2.7/site-packages/flask/app.py", line 1598, in dispatch_request
    return self.view_functions[rule.endpoint](**req.view_args)
  File "/home/gray/.pyenv/versions/2.7/envs/psiturkpy/lib/python2.7/site-packages/psiturk/experiment.py", line 733, in regularpage
    return render_template(foldername+"/"+pagename)
  File "/home/gray/.pyenv/versions/2.7/envs/psiturkpy/lib/python2.7/site-packages/flask/templating.py", line 133, in render_template
    return _render(ctx.app.jinja_env.get_or_select_template(template_name_or_list),
  File "/home/gray/.pyenv/versions/2.7/envs/psiturkpy/lib/python2.7/site-packages/jinja2/environment.py", line 869, in get_or_select_template
    return self.get_template(template_name_or_list, parent, globals)
  File "/home/gray/.pyenv/versions/2.7/envs/psiturkpy/lib/python2.7/site-packages/jinja2/environment.py", line 830, in get_template
    return self._load_template(name, self.make_globals(globals))
  File "/home/gray/.pyenv/versions/2.7/envs/psiturkpy/lib/python2.7/site-packages/jinja2/environment.py", line 804, in _load_template
    template = self.loader.load(self, name, globals)
  File "/home/gray/.pyenv/versions/2.7/envs/psiturkpy/lib/python2.7/site-packages/jinja2/loaders.py", line 113, in load
    source, filename, uptodate = self.get_source(environment, name)
  File "/home/gray/.pyenv/versions/2.7/envs/psiturkpy/lib/python2.7/site-packages/flask/templating.py", line 57, in get_source
    return self._get_source_fast(environment, template)
  File "/home/gray/.pyenv/versions/2.7/envs/psiturkpy/lib/python2.7/site-packages/flask/templating.py", line 85, in _get_source_fast
    raise TemplateNotFound(template)
TemplateNotFound: scripts/main.js
[2019-04-02 23:24:04,314] ERROR in app: Exception on /scripts/main.js [GET]
Traceback (most recent call last):
  File "/home/gray/.pyenv/versions/2.7/envs/psiturkpy/lib/python2.7/site-packages/flask/app.py", line 1982, in wsgi_app
    response = self.full_dispatch_request()
  File "/home/gray/.pyenv/versions/2.7/envs/psiturkpy/lib/python2.7/site-packages/flask/app.py", line 1614, in full_dispatch_request
    rv = self.handle_user_exception(e)
  File "/home/gray/.pyenv/versions/2.7/envs/psiturkpy/lib/python2.7/site-packages/flask/app.py", line 1517, in handle_user_exception
    reraise(exc_type, exc_value, tb)
  File "/home/gray/.pyenv/versions/2.7/envs/psiturkpy/lib/python2.7/site-packages/flask/app.py", line 1612, in full_dispatch_request
    rv = self.dispatch_request()
  File "/home/gray/.pyenv/versions/2.7/envs/psiturkpy/lib/python2.7/site-packages/flask/app.py", line 1598, in dispatch_request
    return self.view_functions[rule.endpoint](**req.view_args)
  File "/home/gray/.pyenv/versions/2.7/envs/psiturkpy/lib/python2.7/site-packages/psiturk/experiment.py", line 733, in regularpage
    return render_template(foldername+"/"+pagename)
  File "/home/gray/.pyenv/versions/2.7/envs/psiturkpy/lib/python2.7/site-packages/flask/templating.py", line 133, in render_template
    return _render(ctx.app.jinja_env.get_or_select_template(template_name_or_list),
  File "/home/gray/.pyenv/versions/2.7/envs/psiturkpy/lib/python2.7/site-packages/jinja2/environment.py", line 869, in get_or_select_template
    return self.get_template(template_name_or_list, parent, globals)
  File "/home/gray/.pyenv/versions/2.7/envs/psiturkpy/lib/python2.7/site-packages/jinja2/environment.py", line 830, in get_template
    return self._load_template(name, self.make_globals(globals))
  File "/home/gray/.pyenv/versions/2.7/envs/psiturkpy/lib/python2.7/site-packages/jinja2/environment.py", line 804, in _load_template
    template = self.loader.load(self, name, globals)
  File "/home/gray/.pyenv/versions/2.7/envs/psiturkpy/lib/python2.7/site-packages/jinja2/loaders.py", line 113, in load
    source, filename, uptodate = self.get_source(environment, name)
  File "/home/gray/.pyenv/versions/2.7/envs/psiturkpy/lib/python2.7/site-packages/flask/templating.py", line 57, in get_source
    return self._get_source_fast(environment, template)
  File "/home/gray/.pyenv/versions/2.7/envs/psiturkpy/lib/python2.7/site-packages/flask/templating.py", line 85, in _get_source_fast
    raise TemplateNotFound(template)
TemplateNotFound: scripts/main.js
[2019-04-02 23:25:37,745] ERROR in app: Exception on /scripts/main.js [GET]
Traceback (most recent call last):
  File "/home/gray/.pyenv/versions/2.7/envs/psiturkpy/lib/python2.7/site-packages/flask/app.py", line 1982, in wsgi_app
    response = self.full_dispatch_request()
  File "/home/gray/.pyenv/versions/2.7/envs/psiturkpy/lib/python2.7/site-packages/flask/app.py", line 1614, in full_dispatch_request
    rv = self.handle_user_exception(e)
  File "/home/gray/.pyenv/versions/2.7/envs/psiturkpy/lib/python2.7/site-packages/flask/app.py", line 1517, in handle_user_exception
    reraise(exc_type, exc_value, tb)
  File "/home/gray/.pyenv/versions/2.7/envs/psiturkpy/lib/python2.7/site-packages/flask/app.py", line 1612, in full_dispatch_request
    rv = self.dispatch_request()
  File "/home/gray/.pyenv/versions/2.7/envs/psiturkpy/lib/python2.7/site-packages/flask/app.py", line 1598, in dispatch_request
    return self.view_functions[rule.endpoint](**req.view_args)
  File "/home/gray/.pyenv/versions/2.7/envs/psiturkpy/lib/python2.7/site-packages/psiturk/experiment.py", line 733, in regularpage
    return render_template(foldername+"/"+pagename)
  File "/home/gray/.pyenv/versions/2.7/envs/psiturkpy/lib/python2.7/site-packages/flask/templating.py", line 133, in render_template
    return _render(ctx.app.jinja_env.get_or_select_template(template_name_or_list),
  File "/home/gray/.pyenv/versions/2.7/envs/psiturkpy/lib/python2.7/site-packages/jinja2/environment.py", line 869, in get_or_select_template
    return self.get_template(template_name_or_list, parent, globals)
  File "/home/gray/.pyenv/versions/2.7/envs/psiturkpy/lib/python2.7/site-packages/jinja2/environment.py", line 830, in get_template
    return self._load_template(name, self.make_globals(globals))
  File "/home/gray/.pyenv/versions/2.7/envs/psiturkpy/lib/python2.7/site-packages/jinja2/environment.py", line 804, in _load_template
    template = self.loader.load(self, name, globals)
  File "/home/gray/.pyenv/versions/2.7/envs/psiturkpy/lib/python2.7/site-packages/jinja2/loaders.py", line 113, in load
    source, filename, uptodate = self.get_source(environment, name)
  File "/home/gray/.pyenv/versions/2.7/envs/psiturkpy/lib/python2.7/site-packages/flask/templating.py", line 57, in get_source
    return self._get_source_fast(environment, template)
  File "/home/gray/.pyenv/versions/2.7/envs/psiturkpy/lib/python2.7/site-packages/flask/templating.py", line 85, in _get_source_fast
    raise TemplateNotFound(template)
TemplateNotFound: scripts/main.js
[2019-04-02 23:26:03,185] ERROR in app: Exception on /scripts/main.js [GET]
Traceback (most recent call last):
  File "/home/gray/.pyenv/versions/2.7/envs/psiturkpy/lib/python2.7/site-packages/flask/app.py", line 1982, in wsgi_app
    response = self.full_dispatch_request()
  File "/home/gray/.pyenv/versions/2.7/envs/psiturkpy/lib/python2.7/site-packages/flask/app.py", line 1614, in full_dispatch_request
    rv = self.handle_user_exception(e)
  File "/home/gray/.pyenv/versions/2.7/envs/psiturkpy/lib/python2.7/site-packages/flask/app.py", line 1517, in handle_user_exception
    reraise(exc_type, exc_value, tb)
  File "/home/gray/.pyenv/versions/2.7/envs/psiturkpy/lib/python2.7/site-packages/flask/app.py", line 1612, in full_dispatch_request
    rv = self.dispatch_request()
  File "/home/gray/.pyenv/versions/2.7/envs/psiturkpy/lib/python2.7/site-packages/flask/app.py", line 1598, in dispatch_request
    return self.view_functions[rule.endpoint](**req.view_args)
  File "/home/gray/.pyenv/versions/2.7/envs/psiturkpy/lib/python2.7/site-packages/psiturk/experiment.py", line 733, in regularpage
    return render_template(foldername+"/"+pagename)
  File "/home/gray/.pyenv/versions/2.7/envs/psiturkpy/lib/python2.7/site-packages/flask/templating.py", line 133, in render_template
    return _render(ctx.app.jinja_env.get_or_select_template(template_name_or_list),
  File "/home/gray/.pyenv/versions/2.7/envs/psiturkpy/lib/python2.7/site-packages/jinja2/environment.py", line 869, in get_or_select_template
    return self.get_template(template_name_or_list, parent, globals)
  File "/home/gray/.pyenv/versions/2.7/envs/psiturkpy/lib/python2.7/site-packages/jinja2/environment.py", line 830, in get_template
    return self._load_template(name, self.make_globals(globals))
  File "/home/gray/.pyenv/versions/2.7/envs/psiturkpy/lib/python2.7/site-packages/jinja2/environment.py", line 804, in _load_template
    template = self.loader.load(self, name, globals)
  File "/home/gray/.pyenv/versions/2.7/envs/psiturkpy/lib/python2.7/site-packages/jinja2/loaders.py", line 113, in load
    source, filename, uptodate = self.get_source(environment, name)
  File "/home/gray/.pyenv/versions/2.7/envs/psiturkpy/lib/python2.7/site-packages/flask/templating.py", line 57, in get_source
    return self._get_source_fast(environment, template)
  File "/home/gray/.pyenv/versions/2.7/envs/psiturkpy/lib/python2.7/site-packages/flask/templating.py", line 85, in _get_source_fast
    raise TemplateNotFound(template)
TemplateNotFound: scripts/main.js
[2019-04-02 23:26:33,910] ERROR in app: Exception on /scripts/main.js [GET]
Traceback (most recent call last):
  File "/home/gray/.pyenv/versions/2.7/envs/psiturkpy/lib/python2.7/site-packages/flask/app.py", line 1982, in wsgi_app
    response = self.full_dispatch_request()
  File "/home/gray/.pyenv/versions/2.7/envs/psiturkpy/lib/python2.7/site-packages/flask/app.py", line 1614, in full_dispatch_request
    rv = self.handle_user_exception(e)
  File "/home/gray/.pyenv/versions/2.7/envs/psiturkpy/lib/python2.7/site-packages/flask/app.py", line 1517, in handle_user_exception
    reraise(exc_type, exc_value, tb)
  File "/home/gray/.pyenv/versions/2.7/envs/psiturkpy/lib/python2.7/site-packages/flask/app.py", line 1612, in full_dispatch_request
    rv = self.dispatch_request()
  File "/home/gray/.pyenv/versions/2.7/envs/psiturkpy/lib/python2.7/site-packages/flask/app.py", line 1598, in dispatch_request
    return self.view_functions[rule.endpoint](**req.view_args)
  File "/home/gray/.pyenv/versions/2.7/envs/psiturkpy/lib/python2.7/site-packages/psiturk/experiment.py", line 733, in regularpage
    return render_template(foldername+"/"+pagename)
  File "/home/gray/.pyenv/versions/2.7/envs/psiturkpy/lib/python2.7/site-packages/flask/templating.py", line 133, in render_template
    return _render(ctx.app.jinja_env.get_or_select_template(template_name_or_list),
  File "/home/gray/.pyenv/versions/2.7/envs/psiturkpy/lib/python2.7/site-packages/jinja2/environment.py", line 869, in get_or_select_template
    return self.get_template(template_name_or_list, parent, globals)
  File "/home/gray/.pyenv/versions/2.7/envs/psiturkpy/lib/python2.7/site-packages/jinja2/environment.py", line 830, in get_template
    return self._load_template(name, self.make_globals(globals))
  File "/home/gray/.pyenv/versions/2.7/envs/psiturkpy/lib/python2.7/site-packages/jinja2/environment.py", line 804, in _load_template
    template = self.loader.load(self, name, globals)
  File "/home/gray/.pyenv/versions/2.7/envs/psiturkpy/lib/python2.7/site-packages/jinja2/loaders.py", line 113, in load
    source, filename, uptodate = self.get_source(environment, name)
  File "/home/gray/.pyenv/versions/2.7/envs/psiturkpy/lib/python2.7/site-packages/flask/templating.py", line 57, in get_source
    return self._get_source_fast(environment, template)
  File "/home/gray/.pyenv/versions/2.7/envs/psiturkpy/lib/python2.7/site-packages/flask/templating.py", line 85, in _get_source_fast
    raise TemplateNotFound(template)
TemplateNotFound: scripts/main.js
[2019-04-02 23:26:46,634] ERROR in app: Exception on /scripts/main.js [GET]
Traceback (most recent call last):
  File "/home/gray/.pyenv/versions/2.7/envs/psiturkpy/lib/python2.7/site-packages/flask/app.py", line 1982, in wsgi_app
    response = self.full_dispatch_request()
  File "/home/gray/.pyenv/versions/2.7/envs/psiturkpy/lib/python2.7/site-packages/flask/app.py", line 1614, in full_dispatch_request
    rv = self.handle_user_exception(e)
  File "/home/gray/.pyenv/versions/2.7/envs/psiturkpy/lib/python2.7/site-packages/flask/app.py", line 1517, in handle_user_exception
    reraise(exc_type, exc_value, tb)
  File "/home/gray/.pyenv/versions/2.7/envs/psiturkpy/lib/python2.7/site-packages/flask/app.py", line 1612, in full_dispatch_request
    rv = self.dispatch_request()
  File "/home/gray/.pyenv/versions/2.7/envs/psiturkpy/lib/python2.7/site-packages/flask/app.py", line 1598, in dispatch_request
    return self.view_functions[rule.endpoint](**req.view_args)
  File "/home/gray/.pyenv/versions/2.7/envs/psiturkpy/lib/python2.7/site-packages/psiturk/experiment.py", line 733, in regularpage
    return render_template(foldername+"/"+pagename)
  File "/home/gray/.pyenv/versions/2.7/envs/psiturkpy/lib/python2.7/site-packages/flask/templating.py", line 133, in render_template
    return _render(ctx.app.jinja_env.get_or_select_template(template_name_or_list),
  File "/home/gray/.pyenv/versions/2.7/envs/psiturkpy/lib/python2.7/site-packages/jinja2/environment.py", line 869, in get_or_select_template
    return self.get_template(template_name_or_list, parent, globals)
  File "/home/gray/.pyenv/versions/2.7/envs/psiturkpy/lib/python2.7/site-packages/jinja2/environment.py", line 830, in get_template
    return self._load_template(name, self.make_globals(globals))
  File "/home/gray/.pyenv/versions/2.7/envs/psiturkpy/lib/python2.7/site-packages/jinja2/environment.py", line 804, in _load_template
    template = self.loader.load(self, name, globals)
  File "/home/gray/.pyenv/versions/2.7/envs/psiturkpy/lib/python2.7/site-packages/jinja2/loaders.py", line 113, in load
    source, filename, uptodate = self.get_source(environment, name)
  File "/home/gray/.pyenv/versions/2.7/envs/psiturkpy/lib/python2.7/site-packages/flask/templating.py", line 57, in get_source
    return self._get_source_fast(environment, template)
  File "/home/gray/.pyenv/versions/2.7/envs/psiturkpy/lib/python2.7/site-packages/flask/templating.py", line 85, in _get_source_fast
    raise TemplateNotFound(template)
TemplateNotFound: scripts/main.js
[2019-04-02 23:27:09,260] ERROR in app: Exception on /scripts/main.js [GET]
Traceback (most recent call last):
  File "/home/gray/.pyenv/versions/2.7/envs/psiturkpy/lib/python2.7/site-packages/flask/app.py", line 1982, in wsgi_app
    response = self.full_dispatch_request()
  File "/home/gray/.pyenv/versions/2.7/envs/psiturkpy/lib/python2.7/site-packages/flask/app.py", line 1614, in full_dispatch_request
    rv = self.handle_user_exception(e)
  File "/home/gray/.pyenv/versions/2.7/envs/psiturkpy/lib/python2.7/site-packages/flask/app.py", line 1517, in handle_user_exception
    reraise(exc_type, exc_value, tb)
  File "/home/gray/.pyenv/versions/2.7/envs/psiturkpy/lib/python2.7/site-packages/flask/app.py", line 1612, in full_dispatch_request
    rv = self.dispatch_request()
  File "/home/gray/.pyenv/versions/2.7/envs/psiturkpy/lib/python2.7/site-packages/flask/app.py", line 1598, in dispatch_request
    return self.view_functions[rule.endpoint](**req.view_args)
  File "/home/gray/.pyenv/versions/2.7/envs/psiturkpy/lib/python2.7/site-packages/psiturk/experiment.py", line 733, in regularpage
    return render_template(foldername+"/"+pagename)
  File "/home/gray/.pyenv/versions/2.7/envs/psiturkpy/lib/python2.7/site-packages/flask/templating.py", line 133, in render_template
    return _render(ctx.app.jinja_env.get_or_select_template(template_name_or_list),
  File "/home/gray/.pyenv/versions/2.7/envs/psiturkpy/lib/python2.7/site-packages/jinja2/environment.py", line 869, in get_or_select_template
    return self.get_template(template_name_or_list, parent, globals)
  File "/home/gray/.pyenv/versions/2.7/envs/psiturkpy/lib/python2.7/site-packages/jinja2/environment.py", line 830, in get_template
    return self._load_template(name, self.make_globals(globals))
  File "/home/gray/.pyenv/versions/2.7/envs/psiturkpy/lib/python2.7/site-packages/jinja2/environment.py", line 804, in _load_template
    template = self.loader.load(self, name, globals)
  File "/home/gray/.pyenv/versions/2.7/envs/psiturkpy/lib/python2.7/site-packages/jinja2/loaders.py", line 113, in load
    source, filename, uptodate = self.get_source(environment, name)
  File "/home/gray/.pyenv/versions/2.7/envs/psiturkpy/lib/python2.7/site-packages/flask/templating.py", line 57, in get_source
    return self._get_source_fast(environment, template)
  File "/home/gray/.pyenv/versions/2.7/envs/psiturkpy/lib/python2.7/site-packages/flask/templating.py", line 85, in _get_source_fast
    raise TemplateNotFound(template)
TemplateNotFound: scripts/main.js
[2019-04-02 23:27:09,263] ERROR in app: Exception on /scripts/jquery.js [GET]
Traceback (most recent call last):
  File "/home/gray/.pyenv/versions/2.7/envs/psiturkpy/lib/python2.7/site-packages/flask/app.py", line 1982, in wsgi_app
    response = self.full_dispatch_request()
  File "/home/gray/.pyenv/versions/2.7/envs/psiturkpy/lib/python2.7/site-packages/flask/app.py", line 1614, in full_dispatch_request
    rv = self.handle_user_exception(e)
  File "/home/gray/.pyenv/versions/2.7/envs/psiturkpy/lib/python2.7/site-packages/flask/app.py", line 1517, in handle_user_exception
    reraise(exc_type, exc_value, tb)
  File "/home/gray/.pyenv/versions/2.7/envs/psiturkpy/lib/python2.7/site-packages/flask/app.py", line 1612, in full_dispatch_request
    rv = self.dispatch_request()
  File "/home/gray/.pyenv/versions/2.7/envs/psiturkpy/lib/python2.7/site-packages/flask/app.py", line 1598, in dispatch_request
    return self.view_functions[rule.endpoint](**req.view_args)
  File "/home/gray/.pyenv/versions/2.7/envs/psiturkpy/lib/python2.7/site-packages/psiturk/experiment.py", line 733, in regularpage
    return render_template(foldername+"/"+pagename)
  File "/home/gray/.pyenv/versions/2.7/envs/psiturkpy/lib/python2.7/site-packages/flask/templating.py", line 133, in render_template
    return _render(ctx.app.jinja_env.get_or_select_template(template_name_or_list),
  File "/home/gray/.pyenv/versions/2.7/envs/psiturkpy/lib/python2.7/site-packages/jinja2/environment.py", line 869, in get_or_select_template
    return self.get_template(template_name_or_list, parent, globals)
  File "/home/gray/.pyenv/versions/2.7/envs/psiturkpy/lib/python2.7/site-packages/jinja2/environment.py", line 830, in get_template
    return self._load_template(name, self.make_globals(globals))
  File "/home/gray/.pyenv/versions/2.7/envs/psiturkpy/lib/python2.7/site-packages/jinja2/environment.py", line 804, in _load_template
    template = self.loader.load(self, name, globals)
  File "/home/gray/.pyenv/versions/2.7/envs/psiturkpy/lib/python2.7/site-packages/jinja2/loaders.py", line 113, in load
    source, filename, uptodate = self.get_source(environment, name)
  File "/home/gray/.pyenv/versions/2.7/envs/psiturkpy/lib/python2.7/site-packages/flask/templating.py", line 57, in get_source
    return self._get_source_fast(environment, template)
  File "/home/gray/.pyenv/versions/2.7/envs/psiturkpy/lib/python2.7/site-packages/flask/templating.py", line 85, in _get_source_fast
    raise TemplateNotFound(template)
TemplateNotFound: scripts/jquery.js
[2019-04-02 23:28:05,387] ERROR in app: Exception on /scripts/main.js [GET]
Traceback (most recent call last):
  File "/home/gray/.pyenv/versions/2.7/envs/psiturkpy/lib/python2.7/site-packages/flask/app.py", line 1982, in wsgi_app
    response = self.full_dispatch_request()
  File "/home/gray/.pyenv/versions/2.7/envs/psiturkpy/lib/python2.7/site-packages/flask/app.py", line 1614, in full_dispatch_request
    rv = self.handle_user_exception(e)
  File "/home/gray/.pyenv/versions/2.7/envs/psiturkpy/lib/python2.7/site-packages/flask/app.py", line 1517, in handle_user_exception
    reraise(exc_type, exc_value, tb)
  File "/home/gray/.pyenv/versions/2.7/envs/psiturkpy/lib/python2.7/site-packages/flask/app.py", line 1612, in full_dispatch_request
    rv = self.dispatch_request()
  File "/home/gray/.pyenv/versions/2.7/envs/psiturkpy/lib/python2.7/site-packages/flask/app.py", line 1598, in dispatch_request
    return self.view_functions[rule.endpoint](**req.view_args)
  File "/home/gray/.pyenv/versions/2.7/envs/psiturkpy/lib/python2.7/site-packages/psiturk/experiment.py", line 733, in regularpage
    return render_template(foldername+"/"+pagename)
  File "/home/gray/.pyenv/versions/2.7/envs/psiturkpy/lib/python2.7/site-packages/flask/templating.py", line 133, in render_template
    return _render(ctx.app.jinja_env.get_or_select_template(template_name_or_list),
  File "/home/gray/.pyenv/versions/2.7/envs/psiturkpy/lib/python2.7/site-packages/jinja2/environment.py", line 869, in get_or_select_template
    return self.get_template(template_name_or_list, parent, globals)
  File "/home/gray/.pyenv/versions/2.7/envs/psiturkpy/lib/python2.7/site-packages/jinja2/environment.py", line 830, in get_template
    return self._load_template(name, self.make_globals(globals))
  File "/home/gray/.pyenv/versions/2.7/envs/psiturkpy/lib/python2.7/site-packages/jinja2/environment.py", line 804, in _load_template
    template = self.loader.load(self, name, globals)
  File "/home/gray/.pyenv/versions/2.7/envs/psiturkpy/lib/python2.7/site-packages/jinja2/loaders.py", line 113, in load
    source, filename, uptodate = self.get_source(environment, name)
  File "/home/gray/.pyenv/versions/2.7/envs/psiturkpy/lib/python2.7/site-packages/flask/templating.py", line 57, in get_source
    return self._get_source_fast(environment, template)
  File "/home/gray/.pyenv/versions/2.7/envs/psiturkpy/lib/python2.7/site-packages/flask/templating.py", line 85, in _get_source_fast
    raise TemplateNotFound(template)
TemplateNotFound: scripts/main.js
[2019-04-02 23:28:05,391] ERROR in app: Exception on /scripts/jquery.js [GET]
Traceback (most recent call last):
  File "/home/gray/.pyenv/versions/2.7/envs/psiturkpy/lib/python2.7/site-packages/flask/app.py", line 1982, in wsgi_app
    response = self.full_dispatch_request()
  File "/home/gray/.pyenv/versions/2.7/envs/psiturkpy/lib/python2.7/site-packages/flask/app.py", line 1614, in full_dispatch_request
    rv = self.handle_user_exception(e)
  File "/home/gray/.pyenv/versions/2.7/envs/psiturkpy/lib/python2.7/site-packages/flask/app.py", line 1517, in handle_user_exception
    reraise(exc_type, exc_value, tb)
  File "/home/gray/.pyenv/versions/2.7/envs/psiturkpy/lib/python2.7/site-packages/flask/app.py", line 1612, in full_dispatch_request
    rv = self.dispatch_request()
  File "/home/gray/.pyenv/versions/2.7/envs/psiturkpy/lib/python2.7/site-packages/flask/app.py", line 1598, in dispatch_request
    return self.view_functions[rule.endpoint](**req.view_args)
  File "/home/gray/.pyenv/versions/2.7/envs/psiturkpy/lib/python2.7/site-packages/psiturk/experiment.py", line 733, in regularpage
    return render_template(foldername+"/"+pagename)
  File "/home/gray/.pyenv/versions/2.7/envs/psiturkpy/lib/python2.7/site-packages/flask/templating.py", line 133, in render_template
    return _render(ctx.app.jinja_env.get_or_select_template(template_name_or_list),
  File "/home/gray/.pyenv/versions/2.7/envs/psiturkpy/lib/python2.7/site-packages/jinja2/environment.py", line 869, in get_or_select_template
    return self.get_template(template_name_or_list, parent, globals)
  File "/home/gray/.pyenv/versions/2.7/envs/psiturkpy/lib/python2.7/site-packages/jinja2/environment.py", line 830, in get_template
    return self._load_template(name, self.make_globals(globals))
  File "/home/gray/.pyenv/versions/2.7/envs/psiturkpy/lib/python2.7/site-packages/jinja2/environment.py", line 804, in _load_template
    template = self.loader.load(self, name, globals)
  File "/home/gray/.pyenv/versions/2.7/envs/psiturkpy/lib/python2.7/site-packages/jinja2/loaders.py", line 113, in load
    source, filename, uptodate = self.get_source(environment, name)
  File "/home/gray/.pyenv/versions/2.7/envs/psiturkpy/lib/python2.7/site-packages/flask/templating.py", line 57, in get_source
    return self._get_source_fast(environment, template)
  File "/home/gray/.pyenv/versions/2.7/envs/psiturkpy/lib/python2.7/site-packages/flask/templating.py", line 85, in _get_source_fast
    raise TemplateNotFound(template)
TemplateNotFound: scripts/jquery.js
[2019-04-02 23:30:07,128] ERROR in app: Exception on /scripts/main.js [GET]
Traceback (most recent call last):
  File "/home/gray/.pyenv/versions/2.7/envs/psiturkpy/lib/python2.7/site-packages/flask/app.py", line 1982, in wsgi_app
    response = self.full_dispatch_request()
  File "/home/gray/.pyenv/versions/2.7/envs/psiturkpy/lib/python2.7/site-packages/flask/app.py", line 1614, in full_dispatch_request
    rv = self.handle_user_exception(e)
  File "/home/gray/.pyenv/versions/2.7/envs/psiturkpy/lib/python2.7/site-packages/flask/app.py", line 1517, in handle_user_exception
    reraise(exc_type, exc_value, tb)
  File "/home/gray/.pyenv/versions/2.7/envs/psiturkpy/lib/python2.7/site-packages/flask/app.py", line 1612, in full_dispatch_request
    rv = self.dispatch_request()
  File "/home/gray/.pyenv/versions/2.7/envs/psiturkpy/lib/python2.7/site-packages/flask/app.py", line 1598, in dispatch_request
    return self.view_functions[rule.endpoint](**req.view_args)
  File "/home/gray/.pyenv/versions/2.7/envs/psiturkpy/lib/python2.7/site-packages/psiturk/experiment.py", line 733, in regularpage
    return render_template(foldername+"/"+pagename)
  File "/home/gray/.pyenv/versions/2.7/envs/psiturkpy/lib/python2.7/site-packages/flask/templating.py", line 133, in render_template
    return _render(ctx.app.jinja_env.get_or_select_template(template_name_or_list),
  File "/home/gray/.pyenv/versions/2.7/envs/psiturkpy/lib/python2.7/site-packages/jinja2/environment.py", line 869, in get_or_select_template
    return self.get_template(template_name_or_list, parent, globals)
  File "/home/gray/.pyenv/versions/2.7/envs/psiturkpy/lib/python2.7/site-packages/jinja2/environment.py", line 830, in get_template
    return self._load_template(name, self.make_globals(globals))
  File "/home/gray/.pyenv/versions/2.7/envs/psiturkpy/lib/python2.7/site-packages/jinja2/environment.py", line 804, in _load_template
    template = self.loader.load(self, name, globals)
  File "/home/gray/.pyenv/versions/2.7/envs/psiturkpy/lib/python2.7/site-packages/jinja2/loaders.py", line 113, in load
    source, filename, uptodate = self.get_source(environment, name)
  File "/home/gray/.pyenv/versions/2.7/envs/psiturkpy/lib/python2.7/site-packages/flask/templating.py", line 57, in get_source
    return self._get_source_fast(environment, template)
  File "/home/gray/.pyenv/versions/2.7/envs/psiturkpy/lib/python2.7/site-packages/flask/templating.py", line 85, in _get_source_fast
    raise TemplateNotFound(template)
TemplateNotFound: scripts/main.js
[2019-04-02 23:30:07,131] ERROR in app: Exception on /scripts/jquery.js [GET]
Traceback (most recent call last):
  File "/home/gray/.pyenv/versions/2.7/envs/psiturkpy/lib/python2.7/site-packages/flask/app.py", line 1982, in wsgi_app
    response = self.full_dispatch_request()
  File "/home/gray/.pyenv/versions/2.7/envs/psiturkpy/lib/python2.7/site-packages/flask/app.py", line 1614, in full_dispatch_request
    rv = self.handle_user_exception(e)
  File "/home/gray/.pyenv/versions/2.7/envs/psiturkpy/lib/python2.7/site-packages/flask/app.py", line 1517, in handle_user_exception
    reraise(exc_type, exc_value, tb)
  File "/home/gray/.pyenv/versions/2.7/envs/psiturkpy/lib/python2.7/site-packages/flask/app.py", line 1612, in full_dispatch_request
    rv = self.dispatch_request()
  File "/home/gray/.pyenv/versions/2.7/envs/psiturkpy/lib/python2.7/site-packages/flask/app.py", line 1598, in dispatch_request
    return self.view_functions[rule.endpoint](**req.view_args)
  File "/home/gray/.pyenv/versions/2.7/envs/psiturkpy/lib/python2.7/site-packages/psiturk/experiment.py", line 733, in regularpage
    return render_template(foldername+"/"+pagename)
  File "/home/gray/.pyenv/versions/2.7/envs/psiturkpy/lib/python2.7/site-packages/flask/templating.py", line 133, in render_template
    return _render(ctx.app.jinja_env.get_or_select_template(template_name_or_list),
  File "/home/gray/.pyenv/versions/2.7/envs/psiturkpy/lib/python2.7/site-packages/jinja2/environment.py", line 869, in get_or_select_template
    return self.get_template(template_name_or_list, parent, globals)
  File "/home/gray/.pyenv/versions/2.7/envs/psiturkpy/lib/python2.7/site-packages/jinja2/environment.py", line 830, in get_template
    return self._load_template(name, self.make_globals(globals))
  File "/home/gray/.pyenv/versions/2.7/envs/psiturkpy/lib/python2.7/site-packages/jinja2/environment.py", line 804, in _load_template
    template = self.loader.load(self, name, globals)
  File "/home/gray/.pyenv/versions/2.7/envs/psiturkpy/lib/python2.7/site-packages/jinja2/loaders.py", line 113, in load
    source, filename, uptodate = self.get_source(environment, name)
  File "/home/gray/.pyenv/versions/2.7/envs/psiturkpy/lib/python2.7/site-packages/flask/templating.py", line 57, in get_source
    return self._get_source_fast(environment, template)
  File "/home/gray/.pyenv/versions/2.7/envs/psiturkpy/lib/python2.7/site-packages/flask/templating.py", line 85, in _get_source_fast
    raise TemplateNotFound(template)
TemplateNotFound: scripts/jquery.js
[2019-04-02 23:30:51,982] ERROR in app: Exception on /scripts/main.js [GET]
Traceback (most recent call last):
  File "/home/gray/.pyenv/versions/2.7/envs/psiturkpy/lib/python2.7/site-packages/flask/app.py", line 1982, in wsgi_app
    response = self.full_dispatch_request()
  File "/home/gray/.pyenv/versions/2.7/envs/psiturkpy/lib/python2.7/site-packages/flask/app.py", line 1614, in full_dispatch_request
    rv = self.handle_user_exception(e)
  File "/home/gray/.pyenv/versions/2.7/envs/psiturkpy/lib/python2.7/site-packages/flask/app.py", line 1517, in handle_user_exception
    reraise(exc_type, exc_value, tb)
  File "/home/gray/.pyenv/versions/2.7/envs/psiturkpy/lib/python2.7/site-packages/flask/app.py", line 1612, in full_dispatch_request
    rv = self.dispatch_request()
  File "/home/gray/.pyenv/versions/2.7/envs/psiturkpy/lib/python2.7/site-packages/flask/app.py", line 1598, in dispatch_request
    return self.view_functions[rule.endpoint](**req.view_args)
  File "/home/gray/.pyenv/versions/2.7/envs/psiturkpy/lib/python2.7/site-packages/psiturk/experiment.py", line 733, in regularpage
    return render_template(foldername+"/"+pagename)
  File "/home/gray/.pyenv/versions/2.7/envs/psiturkpy/lib/python2.7/site-packages/flask/templating.py", line 133, in render_template
    return _render(ctx.app.jinja_env.get_or_select_template(template_name_or_list),
  File "/home/gray/.pyenv/versions/2.7/envs/psiturkpy/lib/python2.7/site-packages/jinja2/environment.py", line 869, in get_or_select_template
    return self.get_template(template_name_or_list, parent, globals)
  File "/home/gray/.pyenv/versions/2.7/envs/psiturkpy/lib/python2.7/site-packages/jinja2/environment.py", line 830, in get_template
    return self._load_template(name, self.make_globals(globals))
  File "/home/gray/.pyenv/versions/2.7/envs/psiturkpy/lib/python2.7/site-packages/jinja2/environment.py", line 804, in _load_template
    template = self.loader.load(self, name, globals)
  File "/home/gray/.pyenv/versions/2.7/envs/psiturkpy/lib/python2.7/site-packages/jinja2/loaders.py", line 113, in load
    source, filename, uptodate = self.get_source(environment, name)
  File "/home/gray/.pyenv/versions/2.7/envs/psiturkpy/lib/python2.7/site-packages/flask/templating.py", line 57, in get_source
    return self._get_source_fast(environment, template)
  File "/home/gray/.pyenv/versions/2.7/envs/psiturkpy/lib/python2.7/site-packages/flask/templating.py", line 85, in _get_source_fast
    raise TemplateNotFound(template)
TemplateNotFound: scripts/main.js
[2019-04-02 23:30:51,985] ERROR in app: Exception on /scripts/jquery.js [GET]
Traceback (most recent call last):
  File "/home/gray/.pyenv/versions/2.7/envs/psiturkpy/lib/python2.7/site-packages/flask/app.py", line 1982, in wsgi_app
    response = self.full_dispatch_request()
  File "/home/gray/.pyenv/versions/2.7/envs/psiturkpy/lib/python2.7/site-packages/flask/app.py", line 1614, in full_dispatch_request
    rv = self.handle_user_exception(e)
  File "/home/gray/.pyenv/versions/2.7/envs/psiturkpy/lib/python2.7/site-packages/flask/app.py", line 1517, in handle_user_exception
    reraise(exc_type, exc_value, tb)
  File "/home/gray/.pyenv/versions/2.7/envs/psiturkpy/lib/python2.7/site-packages/flask/app.py", line 1612, in full_dispatch_request
    rv = self.dispatch_request()
  File "/home/gray/.pyenv/versions/2.7/envs/psiturkpy/lib/python2.7/site-packages/flask/app.py", line 1598, in dispatch_request
    return self.view_functions[rule.endpoint](**req.view_args)
  File "/home/gray/.pyenv/versions/2.7/envs/psiturkpy/lib/python2.7/site-packages/psiturk/experiment.py", line 733, in regularpage
    return render_template(foldername+"/"+pagename)
  File "/home/gray/.pyenv/versions/2.7/envs/psiturkpy/lib/python2.7/site-packages/flask/templating.py", line 133, in render_template
    return _render(ctx.app.jinja_env.get_or_select_template(template_name_or_list),
  File "/home/gray/.pyenv/versions/2.7/envs/psiturkpy/lib/python2.7/site-packages/jinja2/environment.py", line 869, in get_or_select_template
    return self.get_template(template_name_or_list, parent, globals)
  File "/home/gray/.pyenv/versions/2.7/envs/psiturkpy/lib/python2.7/site-packages/jinja2/environment.py", line 830, in get_template
    return self._load_template(name, self.make_globals(globals))
  File "/home/gray/.pyenv/versions/2.7/envs/psiturkpy/lib/python2.7/site-packages/jinja2/environment.py", line 804, in _load_template
    template = self.loader.load(self, name, globals)
  File "/home/gray/.pyenv/versions/2.7/envs/psiturkpy/lib/python2.7/site-packages/jinja2/loaders.py", line 113, in load
    source, filename, uptodate = self.get_source(environment, name)
  File "/home/gray/.pyenv/versions/2.7/envs/psiturkpy/lib/python2.7/site-packages/flask/templating.py", line 57, in get_source
    return self._get_source_fast(environment, template)
  File "/home/gray/.pyenv/versions/2.7/envs/psiturkpy/lib/python2.7/site-packages/flask/templating.py", line 85, in _get_source_fast
    raise TemplateNotFound(template)
TemplateNotFound: scripts/jquery.js
[2019-04-02 23:35:51,628] ERROR in app: Exception on /scripts/main.js [GET]
Traceback (most recent call last):
  File "/home/gray/.pyenv/versions/2.7/envs/psiturkpy/lib/python2.7/site-packages/flask/app.py", line 1982, in wsgi_app
    response = self.full_dispatch_request()
  File "/home/gray/.pyenv/versions/2.7/envs/psiturkpy/lib/python2.7/site-packages/flask/app.py", line 1614, in full_dispatch_request
    rv = self.handle_user_exception(e)
  File "/home/gray/.pyenv/versions/2.7/envs/psiturkpy/lib/python2.7/site-packages/flask/app.py", line 1517, in handle_user_exception
    reraise(exc_type, exc_value, tb)
  File "/home/gray/.pyenv/versions/2.7/envs/psiturkpy/lib/python2.7/site-packages/flask/app.py", line 1612, in full_dispatch_request
    rv = self.dispatch_request()
  File "/home/gray/.pyenv/versions/2.7/envs/psiturkpy/lib/python2.7/site-packages/flask/app.py", line 1598, in dispatch_request
    return self.view_functions[rule.endpoint](**req.view_args)
  File "/home/gray/.pyenv/versions/2.7/envs/psiturkpy/lib/python2.7/site-packages/psiturk/experiment.py", line 733, in regularpage
    return render_template(foldername+"/"+pagename)
  File "/home/gray/.pyenv/versions/2.7/envs/psiturkpy/lib/python2.7/site-packages/flask/templating.py", line 133, in render_template
    return _render(ctx.app.jinja_env.get_or_select_template(template_name_or_list),
  File "/home/gray/.pyenv/versions/2.7/envs/psiturkpy/lib/python2.7/site-packages/jinja2/environment.py", line 869, in get_or_select_template
    return self.get_template(template_name_or_list, parent, globals)
  File "/home/gray/.pyenv/versions/2.7/envs/psiturkpy/lib/python2.7/site-packages/jinja2/environment.py", line 830, in get_template
    return self._load_template(name, self.make_globals(globals))
  File "/home/gray/.pyenv/versions/2.7/envs/psiturkpy/lib/python2.7/site-packages/jinja2/environment.py", line 804, in _load_template
    template = self.loader.load(self, name, globals)
  File "/home/gray/.pyenv/versions/2.7/envs/psiturkpy/lib/python2.7/site-packages/jinja2/loaders.py", line 113, in load
    source, filename, uptodate = self.get_source(environment, name)
  File "/home/gray/.pyenv/versions/2.7/envs/psiturkpy/lib/python2.7/site-packages/flask/templating.py", line 57, in get_source
    return self._get_source_fast(environment, template)
  File "/home/gray/.pyenv/versions/2.7/envs/psiturkpy/lib/python2.7/site-packages/flask/templating.py", line 85, in _get_source_fast
    raise TemplateNotFound(template)
TemplateNotFound: scripts/main.js
[2019-04-02 23:35:51,630] ERROR in app: Exception on /scripts/jquery.js [GET]
Traceback (most recent call last):
  File "/home/gray/.pyenv/versions/2.7/envs/psiturkpy/lib/python2.7/site-packages/flask/app.py", line 1982, in wsgi_app
    response = self.full_dispatch_request()
  File "/home/gray/.pyenv/versions/2.7/envs/psiturkpy/lib/python2.7/site-packages/flask/app.py", line 1614, in full_dispatch_request
    rv = self.handle_user_exception(e)
  File "/home/gray/.pyenv/versions/2.7/envs/psiturkpy/lib/python2.7/site-packages/flask/app.py", line 1517, in handle_user_exception
    reraise(exc_type, exc_value, tb)
  File "/home/gray/.pyenv/versions/2.7/envs/psiturkpy/lib/python2.7/site-packages/flask/app.py", line 1612, in full_dispatch_request
    rv = self.dispatch_request()
  File "/home/gray/.pyenv/versions/2.7/envs/psiturkpy/lib/python2.7/site-packages/flask/app.py", line 1598, in dispatch_request
    return self.view_functions[rule.endpoint](**req.view_args)
  File "/home/gray/.pyenv/versions/2.7/envs/psiturkpy/lib/python2.7/site-packages/psiturk/experiment.py", line 733, in regularpage
    return render_template(foldername+"/"+pagename)
  File "/home/gray/.pyenv/versions/2.7/envs/psiturkpy/lib/python2.7/site-packages/flask/templating.py", line 133, in render_template
    return _render(ctx.app.jinja_env.get_or_select_template(template_name_or_list),
  File "/home/gray/.pyenv/versions/2.7/envs/psiturkpy/lib/python2.7/site-packages/jinja2/environment.py", line 869, in get_or_select_template
    return self.get_template(template_name_or_list, parent, globals)
  File "/home/gray/.pyenv/versions/2.7/envs/psiturkpy/lib/python2.7/site-packages/jinja2/environment.py", line 830, in get_template
    return self._load_template(name, self.make_globals(globals))
  File "/home/gray/.pyenv/versions/2.7/envs/psiturkpy/lib/python2.7/site-packages/jinja2/environment.py", line 804, in _load_template
    template = self.loader.load(self, name, globals)
  File "/home/gray/.pyenv/versions/2.7/envs/psiturkpy/lib/python2.7/site-packages/jinja2/loaders.py", line 113, in load
    source, filename, uptodate = self.get_source(environment, name)
  File "/home/gray/.pyenv/versions/2.7/envs/psiturkpy/lib/python2.7/site-packages/flask/templating.py", line 57, in get_source
    return self._get_source_fast(environment, template)
  File "/home/gray/.pyenv/versions/2.7/envs/psiturkpy/lib/python2.7/site-packages/flask/templating.py", line 85, in _get_source_fast
    raise TemplateNotFound(template)
TemplateNotFound: scripts/jquery.js
[2019-04-02 23:36:20,967] ERROR in app: Exception on /scripts/main.js [GET]
Traceback (most recent call last):
  File "/home/gray/.pyenv/versions/2.7/envs/psiturkpy/lib/python2.7/site-packages/flask/app.py", line 1982, in wsgi_app
    response = self.full_dispatch_request()
  File "/home/gray/.pyenv/versions/2.7/envs/psiturkpy/lib/python2.7/site-packages/flask/app.py", line 1614, in full_dispatch_request
    rv = self.handle_user_exception(e)
  File "/home/gray/.pyenv/versions/2.7/envs/psiturkpy/lib/python2.7/site-packages/flask/app.py", line 1517, in handle_user_exception
    reraise(exc_type, exc_value, tb)
  File "/home/gray/.pyenv/versions/2.7/envs/psiturkpy/lib/python2.7/site-packages/flask/app.py", line 1612, in full_dispatch_request
    rv = self.dispatch_request()
  File "/home/gray/.pyenv/versions/2.7/envs/psiturkpy/lib/python2.7/site-packages/flask/app.py", line 1598, in dispatch_request
    return self.view_functions[rule.endpoint](**req.view_args)
  File "/home/gray/.pyenv/versions/2.7/envs/psiturkpy/lib/python2.7/site-packages/psiturk/experiment.py", line 733, in regularpage
    return render_template(foldername+"/"+pagename)
  File "/home/gray/.pyenv/versions/2.7/envs/psiturkpy/lib/python2.7/site-packages/flask/templating.py", line 133, in render_template
    return _render(ctx.app.jinja_env.get_or_select_template(template_name_or_list),
  File "/home/gray/.pyenv/versions/2.7/envs/psiturkpy/lib/python2.7/site-packages/jinja2/environment.py", line 869, in get_or_select_template
    return self.get_template(template_name_or_list, parent, globals)
  File "/home/gray/.pyenv/versions/2.7/envs/psiturkpy/lib/python2.7/site-packages/jinja2/environment.py", line 830, in get_template
    return self._load_template(name, self.make_globals(globals))
  File "/home/gray/.pyenv/versions/2.7/envs/psiturkpy/lib/python2.7/site-packages/jinja2/environment.py", line 804, in _load_template
    template = self.loader.load(self, name, globals)
  File "/home/gray/.pyenv/versions/2.7/envs/psiturkpy/lib/python2.7/site-packages/jinja2/loaders.py", line 113, in load
    source, filename, uptodate = self.get_source(environment, name)
  File "/home/gray/.pyenv/versions/2.7/envs/psiturkpy/lib/python2.7/site-packages/flask/templating.py", line 57, in get_source
    return self._get_source_fast(environment, template)
  File "/home/gray/.pyenv/versions/2.7/envs/psiturkpy/lib/python2.7/site-packages/flask/templating.py", line 85, in _get_source_fast
    raise TemplateNotFound(template)
TemplateNotFound: scripts/main.js
[2019-04-02 23:36:20,968] ERROR in app: Exception on /scripts/jquery.js [GET]
Traceback (most recent call last):
  File "/home/gray/.pyenv/versions/2.7/envs/psiturkpy/lib/python2.7/site-packages/flask/app.py", line 1982, in wsgi_app
    response = self.full_dispatch_request()
  File "/home/gray/.pyenv/versions/2.7/envs/psiturkpy/lib/python2.7/site-packages/flask/app.py", line 1614, in full_dispatch_request
    rv = self.handle_user_exception(e)
  File "/home/gray/.pyenv/versions/2.7/envs/psiturkpy/lib/python2.7/site-packages/flask/app.py", line 1517, in handle_user_exception
    reraise(exc_type, exc_value, tb)
  File "/home/gray/.pyenv/versions/2.7/envs/psiturkpy/lib/python2.7/site-packages/flask/app.py", line 1612, in full_dispatch_request
    rv = self.dispatch_request()
  File "/home/gray/.pyenv/versions/2.7/envs/psiturkpy/lib/python2.7/site-packages/flask/app.py", line 1598, in dispatch_request
    return self.view_functions[rule.endpoint](**req.view_args)
  File "/home/gray/.pyenv/versions/2.7/envs/psiturkpy/lib/python2.7/site-packages/psiturk/experiment.py", line 733, in regularpage
    return render_template(foldername+"/"+pagename)
  File "/home/gray/.pyenv/versions/2.7/envs/psiturkpy/lib/python2.7/site-packages/flask/templating.py", line 133, in render_template
    return _render(ctx.app.jinja_env.get_or_select_template(template_name_or_list),
  File "/home/gray/.pyenv/versions/2.7/envs/psiturkpy/lib/python2.7/site-packages/jinja2/environment.py", line 869, in get_or_select_template
    return self.get_template(template_name_or_list, parent, globals)
  File "/home/gray/.pyenv/versions/2.7/envs/psiturkpy/lib/python2.7/site-packages/jinja2/environment.py", line 830, in get_template
    return self._load_template(name, self.make_globals(globals))
  File "/home/gray/.pyenv/versions/2.7/envs/psiturkpy/lib/python2.7/site-packages/jinja2/environment.py", line 804, in _load_template
    template = self.loader.load(self, name, globals)
  File "/home/gray/.pyenv/versions/2.7/envs/psiturkpy/lib/python2.7/site-packages/jinja2/loaders.py", line 113, in load
    source, filename, uptodate = self.get_source(environment, name)
  File "/home/gray/.pyenv/versions/2.7/envs/psiturkpy/lib/python2.7/site-packages/flask/templating.py", line 57, in get_source
    return self._get_source_fast(environment, template)
  File "/home/gray/.pyenv/versions/2.7/envs/psiturkpy/lib/python2.7/site-packages/flask/templating.py", line 85, in _get_source_fast
    raise TemplateNotFound(template)
TemplateNotFound: scripts/jquery.js
[2019-04-07 21:07:06 +0000] [27394] [CRITICAL] WORKER TIMEOUT (pid:27398)
[2019-04-12 00:21:43 -0600] [2752] [CRITICAL] WORKER TIMEOUT (pid:2755)
[2019-04-12 00:31:26 -0600] [2752] [CRITICAL] WORKER TIMEOUT (pid:2828)
[2019-04-12 01:05:08 -0600] [2752] [CRITICAL] WORKER TIMEOUT (pid:2884)
[2019-04-12 03:15:33,041] ERROR in app: Exception on /undefined [GET]
Traceback (most recent call last):
  File "/usr/local/lib/python2.7/site-packages/flask/app.py", line 1982, in wsgi_app
    response = self.full_dispatch_request()
  File "/usr/local/lib/python2.7/site-packages/flask/app.py", line 1614, in full_dispatch_request
    rv = self.handle_user_exception(e)
  File "/usr/local/lib/python2.7/site-packages/flask/app.py", line 1517, in handle_user_exception
    reraise(exc_type, exc_value, tb)
  File "/usr/local/lib/python2.7/site-packages/flask/app.py", line 1612, in full_dispatch_request
    rv = self.dispatch_request()
  File "/usr/local/lib/python2.7/site-packages/flask/app.py", line 1598, in dispatch_request
    return self.view_functions[rule.endpoint](**req.view_args)
  File "/usr/local/lib/python2.7/site-packages/psiturk/experiment.py", line 731, in regularpage
    return render_template(pagename)
  File "/usr/local/lib/python2.7/site-packages/flask/templating.py", line 133, in render_template
    return _render(ctx.app.jinja_env.get_or_select_template(template_name_or_list),
  File "/usr/local/lib/python2.7/site-packages/jinja2/environment.py", line 869, in get_or_select_template
    return self.get_template(template_name_or_list, parent, globals)
  File "/usr/local/lib/python2.7/site-packages/jinja2/environment.py", line 830, in get_template
    return self._load_template(name, self.make_globals(globals))
  File "/usr/local/lib/python2.7/site-packages/jinja2/environment.py", line 804, in _load_template
    template = self.loader.load(self, name, globals)
  File "/usr/local/lib/python2.7/site-packages/jinja2/loaders.py", line 113, in load
    source, filename, uptodate = self.get_source(environment, name)
  File "/usr/local/lib/python2.7/site-packages/flask/templating.py", line 57, in get_source
    return self._get_source_fast(environment, template)
  File "/usr/local/lib/python2.7/site-packages/flask/templating.py", line 85, in _get_source_fast
    raise TemplateNotFound(template)
TemplateNotFound: undefined
[2019-04-12 03:19:54,012] ERROR in app: Exception on /undefined [GET]
Traceback (most recent call last):
  File "/usr/local/lib/python2.7/site-packages/flask/app.py", line 1982, in wsgi_app
    response = self.full_dispatch_request()
  File "/usr/local/lib/python2.7/site-packages/flask/app.py", line 1614, in full_dispatch_request
    rv = self.handle_user_exception(e)
  File "/usr/local/lib/python2.7/site-packages/flask/app.py", line 1517, in handle_user_exception
    reraise(exc_type, exc_value, tb)
  File "/usr/local/lib/python2.7/site-packages/flask/app.py", line 1612, in full_dispatch_request
    rv = self.dispatch_request()
  File "/usr/local/lib/python2.7/site-packages/flask/app.py", line 1598, in dispatch_request
    return self.view_functions[rule.endpoint](**req.view_args)
  File "/usr/local/lib/python2.7/site-packages/psiturk/experiment.py", line 731, in regularpage
    return render_template(pagename)
  File "/usr/local/lib/python2.7/site-packages/flask/templating.py", line 133, in render_template
    return _render(ctx.app.jinja_env.get_or_select_template(template_name_or_list),
  File "/usr/local/lib/python2.7/site-packages/jinja2/environment.py", line 869, in get_or_select_template
    return self.get_template(template_name_or_list, parent, globals)
  File "/usr/local/lib/python2.7/site-packages/jinja2/environment.py", line 830, in get_template
    return self._load_template(name, self.make_globals(globals))
  File "/usr/local/lib/python2.7/site-packages/jinja2/environment.py", line 804, in _load_template
    template = self.loader.load(self, name, globals)
  File "/usr/local/lib/python2.7/site-packages/jinja2/loaders.py", line 113, in load
    source, filename, uptodate = self.get_source(environment, name)
  File "/usr/local/lib/python2.7/site-packages/flask/templating.py", line 57, in get_source
    return self._get_source_fast(environment, template)
  File "/usr/local/lib/python2.7/site-packages/flask/templating.py", line 85, in _get_source_fast
    raise TemplateNotFound(template)
TemplateNotFound: undefined
[2019-04-12 03:25:47,910] ERROR in app: Exception on /undefined [GET]
Traceback (most recent call last):
  File "/usr/local/lib/python2.7/site-packages/flask/app.py", line 1982, in wsgi_app
    response = self.full_dispatch_request()
  File "/usr/local/lib/python2.7/site-packages/flask/app.py", line 1614, in full_dispatch_request
    rv = self.handle_user_exception(e)
  File "/usr/local/lib/python2.7/site-packages/flask/app.py", line 1517, in handle_user_exception
    reraise(exc_type, exc_value, tb)
  File "/usr/local/lib/python2.7/site-packages/flask/app.py", line 1612, in full_dispatch_request
    rv = self.dispatch_request()
  File "/usr/local/lib/python2.7/site-packages/flask/app.py", line 1598, in dispatch_request
    return self.view_functions[rule.endpoint](**req.view_args)
  File "/usr/local/lib/python2.7/site-packages/psiturk/experiment.py", line 731, in regularpage
    return render_template(pagename)
  File "/usr/local/lib/python2.7/site-packages/flask/templating.py", line 133, in render_template
    return _render(ctx.app.jinja_env.get_or_select_template(template_name_or_list),
  File "/usr/local/lib/python2.7/site-packages/jinja2/environment.py", line 869, in get_or_select_template
    return self.get_template(template_name_or_list, parent, globals)
  File "/usr/local/lib/python2.7/site-packages/jinja2/environment.py", line 830, in get_template
    return self._load_template(name, self.make_globals(globals))
  File "/usr/local/lib/python2.7/site-packages/jinja2/environment.py", line 804, in _load_template
    template = self.loader.load(self, name, globals)
  File "/usr/local/lib/python2.7/site-packages/jinja2/loaders.py", line 113, in load
    source, filename, uptodate = self.get_source(environment, name)
  File "/usr/local/lib/python2.7/site-packages/flask/templating.py", line 57, in get_source
    return self._get_source_fast(environment, template)
  File "/usr/local/lib/python2.7/site-packages/flask/templating.py", line 85, in _get_source_fast
    raise TemplateNotFound(template)
TemplateNotFound: undefined
[2019-04-14 22:50:40 +0000] [4920] [CRITICAL] WORKER TIMEOUT (pid:4926)
[2019-04-16 11:16:38 -0600] [9993] [CRITICAL] WORKER TIMEOUT (pid:9996)
[2019-04-16 11:16:39 -0600] [10111] [ERROR] Exception in worker process:
Traceback (most recent call last):
  File "/usr/local/lib/python2.7/site-packages/gunicorn/arbiter.py", line 515, in spawn_worker
    worker.init_process()
  File "/usr/local/lib/python2.7/site-packages/gunicorn/workers/base.py", line 122, in init_process
    self.load_wsgi()
  File "/usr/local/lib/python2.7/site-packages/gunicorn/workers/base.py", line 130, in load_wsgi
    self.wsgi = self.app.wsgi()
  File "/usr/local/lib/python2.7/site-packages/gunicorn/app/base.py", line 67, in wsgi
    self.callable = self.load()
  File "/usr/local/lib/python2.7/site-packages/psiturk/experiment_server.py", line 48, in load
    return util.import_app("psiturk.experiment:app")
  File "/usr/local/lib/python2.7/site-packages/gunicorn/util.py", line 357, in import_app
    __import__(module)
  File "/usr/local/lib/python2.7/site-packages/psiturk/experiment.py", line 89, in <module>
    init_db()
  File "/usr/local/lib/python2.7/site-packages/psiturk/db.py", line 39, in init_db
    Base.metadata.create_all(bind=engine)
  File "/usr/local/lib/python2.7/site-packages/sqlalchemy/sql/schema.py", line 4287, in create_all
    ddl.SchemaGenerator, self, checkfirst=checkfirst, tables=tables
  File "/usr/local/lib/python2.7/site-packages/sqlalchemy/engine/base.py", line 2032, in _run_visitor
    with self._optional_conn_ctx_manager(connection) as conn:
  File "/usr/local/Cellar/python@2/2.7.16/Frameworks/Python.framework/Versions/2.7/lib/python2.7/contextlib.py", line 17, in __enter__
    return self.gen.next()
  File "/usr/local/lib/python2.7/site-packages/sqlalchemy/engine/base.py", line 2024, in _optional_conn_ctx_manager
    with self._contextual_connect() as conn:
  File "/usr/local/lib/python2.7/site-packages/sqlalchemy/engine/base.py", line 2226, in _contextual_connect
    self._wrap_pool_connect(self.pool.connect, None),
  File "/usr/local/lib/python2.7/site-packages/sqlalchemy/engine/base.py", line 2266, in _wrap_pool_connect
    e, dialect, self
  File "/usr/local/lib/python2.7/site-packages/sqlalchemy/engine/base.py", line 1536, in _handle_dbapi_exception_noconnection
    util.raise_from_cause(sqlalchemy_exception, exc_info)
  File "/usr/local/lib/python2.7/site-packages/sqlalchemy/util/compat.py", line 383, in raise_from_cause
    reraise(type(exception), exception, tb=exc_tb, cause=cause)
  File "/usr/local/lib/python2.7/site-packages/sqlalchemy/engine/base.py", line 2262, in _wrap_pool_connect
    return fn()
  File "/usr/local/lib/python2.7/site-packages/sqlalchemy/pool/base.py", line 354, in connect
    return _ConnectionFairy._checkout(self)
  File "/usr/local/lib/python2.7/site-packages/sqlalchemy/pool/base.py", line 751, in _checkout
    fairy = _ConnectionRecord.checkout(pool)
  File "/usr/local/lib/python2.7/site-packages/sqlalchemy/pool/base.py", line 483, in checkout
    rec = pool._do_get()
  File "/usr/local/lib/python2.7/site-packages/sqlalchemy/pool/impl.py", line 138, in _do_get
    self._dec_overflow()
  File "/usr/local/lib/python2.7/site-packages/sqlalchemy/util/langhelpers.py", line 68, in __exit__
    compat.reraise(exc_type, exc_value, exc_tb)
  File "/usr/local/lib/python2.7/site-packages/sqlalchemy/pool/impl.py", line 135, in _do_get
    return self._create_connection()
  File "/usr/local/lib/python2.7/site-packages/sqlalchemy/pool/base.py", line 299, in _create_connection
    return _ConnectionRecord(self)
  File "/usr/local/lib/python2.7/site-packages/sqlalchemy/pool/base.py", line 428, in __init__
    self.__connect(first_connect_check=True)
  File "/usr/local/lib/python2.7/site-packages/sqlalchemy/pool/base.py", line 630, in __connect
    connection = pool._invoke_creator(self)
  File "/usr/local/lib/python2.7/site-packages/sqlalchemy/engine/strategies.py", line 114, in connect
    return dialect.connect(*cargs, **cparams)
  File "/usr/local/lib/python2.7/site-packages/sqlalchemy/engine/default.py", line 453, in connect
    return self.dbapi.connect(*cargs, **cparams)
  File "/usr/local/lib/python2.7/site-packages/psycopg2/__init__.py", line 130, in connect
    conn = _connect(dsn, connection_factory=connection_factory, **kwasync)
OperationalError: (psycopg2.OperationalError) could not translate host name "ec2-184-72-238-22.compute-1.amazonaws.com" to address: nodename nor servname provided, or not known

(Background on this error at: http://sqlalche.me/e/e3q8)
Traceback (most recent call last):
  File "/usr/local/lib/python2.7/site-packages/gunicorn/arbiter.py", line 515, in spawn_worker
    worker.init_process()
  File "/usr/local/lib/python2.7/site-packages/gunicorn/workers/base.py", line 122, in init_process
    self.load_wsgi()
  File "/usr/local/lib/python2.7/site-packages/gunicorn/workers/base.py", line 130, in load_wsgi
    self.wsgi = self.app.wsgi()
  File "/usr/local/lib/python2.7/site-packages/gunicorn/app/base.py", line 67, in wsgi
    self.callable = self.load()
  File "/usr/local/lib/python2.7/site-packages/psiturk/experiment_server.py", line 48, in load
    return util.import_app("psiturk.experiment:app")
  File "/usr/local/lib/python2.7/site-packages/gunicorn/util.py", line 357, in import_app
    __import__(module)
  File "/usr/local/lib/python2.7/site-packages/psiturk/experiment.py", line 89, in <module>
    init_db()
  File "/usr/local/lib/python2.7/site-packages/psiturk/db.py", line 39, in init_db
    Base.metadata.create_all(bind=engine)
  File "/usr/local/lib/python2.7/site-packages/sqlalchemy/sql/schema.py", line 4287, in create_all
    ddl.SchemaGenerator, self, checkfirst=checkfirst, tables=tables
  File "/usr/local/lib/python2.7/site-packages/sqlalchemy/engine/base.py", line 2032, in _run_visitor
    with self._optional_conn_ctx_manager(connection) as conn:
  File "/usr/local/Cellar/python@2/2.7.16/Frameworks/Python.framework/Versions/2.7/lib/python2.7/contextlib.py", line 17, in __enter__
    return self.gen.next()
  File "/usr/local/lib/python2.7/site-packages/sqlalchemy/engine/base.py", line 2024, in _optional_conn_ctx_manager
    with self._contextual_connect() as conn:
  File "/usr/local/lib/python2.7/site-packages/sqlalchemy/engine/base.py", line 2226, in _contextual_connect
    self._wrap_pool_connect(self.pool.connect, None),
  File "/usr/local/lib/python2.7/site-packages/sqlalchemy/engine/base.py", line 2266, in _wrap_pool_connect
    e, dialect, self
  File "/usr/local/lib/python2.7/site-packages/sqlalchemy/engine/base.py", line 1536, in _handle_dbapi_exception_noconnection
    util.raise_from_cause(sqlalchemy_exception, exc_info)
  File "/usr/local/lib/python2.7/site-packages/sqlalchemy/util/compat.py", line 383, in raise_from_cause
    reraise(type(exception), exception, tb=exc_tb, cause=cause)
  File "/usr/local/lib/python2.7/site-packages/sqlalchemy/engine/base.py", line 2262, in _wrap_pool_connect
    return fn()
  File "/usr/local/lib/python2.7/site-packages/sqlalchemy/pool/base.py", line 354, in connect
    return _ConnectionFairy._checkout(self)
  File "/usr/local/lib/python2.7/site-packages/sqlalchemy/pool/base.py", line 751, in _checkout
    fairy = _ConnectionRecord.checkout(pool)
  File "/usr/local/lib/python2.7/site-packages/sqlalchemy/pool/base.py", line 483, in checkout
    rec = pool._do_get()
  File "/usr/local/lib/python2.7/site-packages/sqlalchemy/pool/impl.py", line 138, in _do_get
    self._dec_overflow()
  File "/usr/local/lib/python2.7/site-packages/sqlalchemy/util/langhelpers.py", line 68, in __exit__
    compat.reraise(exc_type, exc_value, exc_tb)
  File "/usr/local/lib/python2.7/site-packages/sqlalchemy/pool/impl.py", line 135, in _do_get
    return self._create_connection()
  File "/usr/local/lib/python2.7/site-packages/sqlalchemy/pool/base.py", line 299, in _create_connection
    return _ConnectionRecord(self)
  File "/usr/local/lib/python2.7/site-packages/sqlalchemy/pool/base.py", line 428, in __init__
    self.__connect(first_connect_check=True)
  File "/usr/local/lib/python2.7/site-packages/sqlalchemy/pool/base.py", line 630, in __connect
    connection = pool._invoke_creator(self)
  File "/usr/local/lib/python2.7/site-packages/sqlalchemy/engine/strategies.py", line 114, in connect
    return dialect.connect(*cargs, **cparams)
  File "/usr/local/lib/python2.7/site-packages/sqlalchemy/engine/default.py", line 453, in connect
    return self.dbapi.connect(*cargs, **cparams)
  File "/usr/local/lib/python2.7/site-packages/psycopg2/__init__.py", line 130, in connect
    conn = _connect(dsn, connection_factory=connection_factory, **kwasync)
OperationalError: (psycopg2.OperationalError) could not translate host name "ec2-184-72-238-22.compute-1.amazonaws.com" to address: nodename nor servname provided, or not known

(Background on this error at: http://sqlalche.me/e/e3q8)
[2019-04-16 13:55:34 -0600] [10849] [CRITICAL] WORKER TIMEOUT (pid:10852)
[2019-04-16 13:55:37 -0600] [10877] [ERROR] Exception in worker process:
Traceback (most recent call last):
  File "/usr/local/lib/python2.7/site-packages/gunicorn/arbiter.py", line 515, in spawn_worker
    worker.init_process()
  File "/usr/local/lib/python2.7/site-packages/gunicorn/workers/base.py", line 122, in init_process
    self.load_wsgi()
  File "/usr/local/lib/python2.7/site-packages/gunicorn/workers/base.py", line 130, in load_wsgi
    self.wsgi = self.app.wsgi()
  File "/usr/local/lib/python2.7/site-packages/gunicorn/app/base.py", line 67, in wsgi
    self.callable = self.load()
  File "/usr/local/lib/python2.7/site-packages/psiturk/experiment_server.py", line 48, in load
    return util.import_app("psiturk.experiment:app")
  File "/usr/local/lib/python2.7/site-packages/gunicorn/util.py", line 357, in import_app
    __import__(module)
  File "/usr/local/lib/python2.7/site-packages/psiturk/experiment.py", line 89, in <module>
    init_db()
  File "/usr/local/lib/python2.7/site-packages/psiturk/db.py", line 39, in init_db
    Base.metadata.create_all(bind=engine)
  File "/usr/local/lib/python2.7/site-packages/sqlalchemy/sql/schema.py", line 4287, in create_all
    ddl.SchemaGenerator, self, checkfirst=checkfirst, tables=tables
  File "/usr/local/lib/python2.7/site-packages/sqlalchemy/engine/base.py", line 2032, in _run_visitor
    with self._optional_conn_ctx_manager(connection) as conn:
  File "/usr/local/Cellar/python@2/2.7.16/Frameworks/Python.framework/Versions/2.7/lib/python2.7/contextlib.py", line 17, in __enter__
    return self.gen.next()
  File "/usr/local/lib/python2.7/site-packages/sqlalchemy/engine/base.py", line 2024, in _optional_conn_ctx_manager
    with self._contextual_connect() as conn:
  File "/usr/local/lib/python2.7/site-packages/sqlalchemy/engine/base.py", line 2226, in _contextual_connect
    self._wrap_pool_connect(self.pool.connect, None),
  File "/usr/local/lib/python2.7/site-packages/sqlalchemy/engine/base.py", line 2266, in _wrap_pool_connect
    e, dialect, self
  File "/usr/local/lib/python2.7/site-packages/sqlalchemy/engine/base.py", line 1536, in _handle_dbapi_exception_noconnection
    util.raise_from_cause(sqlalchemy_exception, exc_info)
  File "/usr/local/lib/python2.7/site-packages/sqlalchemy/util/compat.py", line 383, in raise_from_cause
    reraise(type(exception), exception, tb=exc_tb, cause=cause)
  File "/usr/local/lib/python2.7/site-packages/sqlalchemy/engine/base.py", line 2262, in _wrap_pool_connect
    return fn()
  File "/usr/local/lib/python2.7/site-packages/sqlalchemy/pool/base.py", line 354, in connect
    return _ConnectionFairy._checkout(self)
  File "/usr/local/lib/python2.7/site-packages/sqlalchemy/pool/base.py", line 751, in _checkout
    fairy = _ConnectionRecord.checkout(pool)
  File "/usr/local/lib/python2.7/site-packages/sqlalchemy/pool/base.py", line 483, in checkout
    rec = pool._do_get()
  File "/usr/local/lib/python2.7/site-packages/sqlalchemy/pool/impl.py", line 138, in _do_get
    self._dec_overflow()
  File "/usr/local/lib/python2.7/site-packages/sqlalchemy/util/langhelpers.py", line 68, in __exit__
    compat.reraise(exc_type, exc_value, exc_tb)
  File "/usr/local/lib/python2.7/site-packages/sqlalchemy/pool/impl.py", line 135, in _do_get
    return self._create_connection()
  File "/usr/local/lib/python2.7/site-packages/sqlalchemy/pool/base.py", line 299, in _create_connection
    return _ConnectionRecord(self)
  File "/usr/local/lib/python2.7/site-packages/sqlalchemy/pool/base.py", line 428, in __init__
    self.__connect(first_connect_check=True)
  File "/usr/local/lib/python2.7/site-packages/sqlalchemy/pool/base.py", line 630, in __connect
    connection = pool._invoke_creator(self)
  File "/usr/local/lib/python2.7/site-packages/sqlalchemy/engine/strategies.py", line 114, in connect
    return dialect.connect(*cargs, **cparams)
  File "/usr/local/lib/python2.7/site-packages/sqlalchemy/engine/default.py", line 453, in connect
    return self.dbapi.connect(*cargs, **cparams)
  File "/usr/local/lib/python2.7/site-packages/psycopg2/__init__.py", line 130, in connect
    conn = _connect(dsn, connection_factory=connection_factory, **kwasync)
OperationalError: (psycopg2.OperationalError) could not translate host name "ec2-184-72-238-22.compute-1.amazonaws.com" to address: nodename nor servname provided, or not known

(Background on this error at: http://sqlalche.me/e/e3q8)
Traceback (most recent call last):
  File "/usr/local/lib/python2.7/site-packages/gunicorn/arbiter.py", line 515, in spawn_worker
    worker.init_process()
  File "/usr/local/lib/python2.7/site-packages/gunicorn/workers/base.py", line 122, in init_process
    self.load_wsgi()
  File "/usr/local/lib/python2.7/site-packages/gunicorn/workers/base.py", line 130, in load_wsgi
    self.wsgi = self.app.wsgi()
  File "/usr/local/lib/python2.7/site-packages/gunicorn/app/base.py", line 67, in wsgi
    self.callable = self.load()
  File "/usr/local/lib/python2.7/site-packages/psiturk/experiment_server.py", line 48, in load
    return util.import_app("psiturk.experiment:app")
  File "/usr/local/lib/python2.7/site-packages/gunicorn/util.py", line 357, in import_app
    __import__(module)
  File "/usr/local/lib/python2.7/site-packages/psiturk/experiment.py", line 89, in <module>
    init_db()
  File "/usr/local/lib/python2.7/site-packages/psiturk/db.py", line 39, in init_db
    Base.metadata.create_all(bind=engine)
  File "/usr/local/lib/python2.7/site-packages/sqlalchemy/sql/schema.py", line 4287, in create_all
    ddl.SchemaGenerator, self, checkfirst=checkfirst, tables=tables
  File "/usr/local/lib/python2.7/site-packages/sqlalchemy/engine/base.py", line 2032, in _run_visitor
    with self._optional_conn_ctx_manager(connection) as conn:
  File "/usr/local/Cellar/python@2/2.7.16/Frameworks/Python.framework/Versions/2.7/lib/python2.7/contextlib.py", line 17, in __enter__
    return self.gen.next()
  File "/usr/local/lib/python2.7/site-packages/sqlalchemy/engine/base.py", line 2024, in _optional_conn_ctx_manager
    with self._contextual_connect() as conn:
  File "/usr/local/lib/python2.7/site-packages/sqlalchemy/engine/base.py", line 2226, in _contextual_connect
    self._wrap_pool_connect(self.pool.connect, None),
  File "/usr/local/lib/python2.7/site-packages/sqlalchemy/engine/base.py", line 2266, in _wrap_pool_connect
    e, dialect, self
  File "/usr/local/lib/python2.7/site-packages/sqlalchemy/engine/base.py", line 1536, in _handle_dbapi_exception_noconnection
    util.raise_from_cause(sqlalchemy_exception, exc_info)
  File "/usr/local/lib/python2.7/site-packages/sqlalchemy/util/compat.py", line 383, in raise_from_cause
    reraise(type(exception), exception, tb=exc_tb, cause=cause)
  File "/usr/local/lib/python2.7/site-packages/sqlalchemy/engine/base.py", line 2262, in _wrap_pool_connect
    return fn()
  File "/usr/local/lib/python2.7/site-packages/sqlalchemy/pool/base.py", line 354, in connect
    return _ConnectionFairy._checkout(self)
  File "/usr/local/lib/python2.7/site-packages/sqlalchemy/pool/base.py", line 751, in _checkout
    fairy = _ConnectionRecord.checkout(pool)
  File "/usr/local/lib/python2.7/site-packages/sqlalchemy/pool/base.py", line 483, in checkout
    rec = pool._do_get()
  File "/usr/local/lib/python2.7/site-packages/sqlalchemy/pool/impl.py", line 138, in _do_get
    self._dec_overflow()
  File "/usr/local/lib/python2.7/site-packages/sqlalchemy/util/langhelpers.py", line 68, in __exit__
    compat.reraise(exc_type, exc_value, exc_tb)
  File "/usr/local/lib/python2.7/site-packages/sqlalchemy/pool/impl.py", line 135, in _do_get
    return self._create_connection()
  File "/usr/local/lib/python2.7/site-packages/sqlalchemy/pool/base.py", line 299, in _create_connection
    return _ConnectionRecord(self)
  File "/usr/local/lib/python2.7/site-packages/sqlalchemy/pool/base.py", line 428, in __init__
    self.__connect(first_connect_check=True)
  File "/usr/local/lib/python2.7/site-packages/sqlalchemy/pool/base.py", line 630, in __connect
    connection = pool._invoke_creator(self)
  File "/usr/local/lib/python2.7/site-packages/sqlalchemy/engine/strategies.py", line 114, in connect
    return dialect.connect(*cargs, **cparams)
  File "/usr/local/lib/python2.7/site-packages/sqlalchemy/engine/default.py", line 453, in connect
    return self.dbapi.connect(*cargs, **cparams)
  File "/usr/local/lib/python2.7/site-packages/psycopg2/__init__.py", line 130, in connect
    conn = _connect(dsn, connection_factory=connection_factory, **kwasync)
OperationalError: (psycopg2.OperationalError) could not translate host name "ec2-184-72-238-22.compute-1.amazonaws.com" to address: nodename nor servname provided, or not known

(Background on this error at: http://sqlalche.me/e/e3q8)
[2019-04-16 14:20:23 -0600] [11284] [CRITICAL] WORKER TIMEOUT (pid:11287)
[2019-04-16 14:20:55 -0600] [11284] [CRITICAL] WORKER TIMEOUT (pid:11302)
[2019-04-16 14:21:59 -0600] [11327] [CRITICAL] WORKER TIMEOUT (pid:11330)
[2019-04-16 14:22:31 -0600] [11327] [CRITICAL] WORKER TIMEOUT (pid:11336)
[2019-04-16 14:45:55 -0600] [11596] [CRITICAL] WORKER TIMEOUT (pid:11599)
[2019-04-16 15:19:25 -0600] [12159] [CRITICAL] WORKER TIMEOUT (pid:12162)
[2019-04-16 15:31:25 -0600] [12212] [CRITICAL] WORKER TIMEOUT (pid:12215)
[2019-04-16 15:31:28 -0600] [12263] [ERROR] Exception in worker process:
Traceback (most recent call last):
  File "/usr/local/lib/python2.7/site-packages/gunicorn/arbiter.py", line 515, in spawn_worker
    worker.init_process()
  File "/usr/local/lib/python2.7/site-packages/gunicorn/workers/base.py", line 122, in init_process
    self.load_wsgi()
  File "/usr/local/lib/python2.7/site-packages/gunicorn/workers/base.py", line 130, in load_wsgi
    self.wsgi = self.app.wsgi()
  File "/usr/local/lib/python2.7/site-packages/gunicorn/app/base.py", line 67, in wsgi
    self.callable = self.load()
  File "/usr/local/lib/python2.7/site-packages/psiturk/experiment_server.py", line 48, in load
    return util.import_app("psiturk.experiment:app")
  File "/usr/local/lib/python2.7/site-packages/gunicorn/util.py", line 357, in import_app
    __import__(module)
  File "/usr/local/lib/python2.7/site-packages/psiturk/experiment.py", line 89, in <module>
    init_db()
  File "/usr/local/lib/python2.7/site-packages/psiturk/db.py", line 39, in init_db
    Base.metadata.create_all(bind=engine)
  File "/usr/local/lib/python2.7/site-packages/sqlalchemy/sql/schema.py", line 4287, in create_all
    ddl.SchemaGenerator, self, checkfirst=checkfirst, tables=tables
  File "/usr/local/lib/python2.7/site-packages/sqlalchemy/engine/base.py", line 2032, in _run_visitor
    with self._optional_conn_ctx_manager(connection) as conn:
  File "/usr/local/Cellar/python@2/2.7.16/Frameworks/Python.framework/Versions/2.7/lib/python2.7/contextlib.py", line 17, in __enter__
    return self.gen.next()
  File "/usr/local/lib/python2.7/site-packages/sqlalchemy/engine/base.py", line 2024, in _optional_conn_ctx_manager
    with self._contextual_connect() as conn:
  File "/usr/local/lib/python2.7/site-packages/sqlalchemy/engine/base.py", line 2226, in _contextual_connect
    self._wrap_pool_connect(self.pool.connect, None),
  File "/usr/local/lib/python2.7/site-packages/sqlalchemy/engine/base.py", line 2266, in _wrap_pool_connect
    e, dialect, self
  File "/usr/local/lib/python2.7/site-packages/sqlalchemy/engine/base.py", line 1536, in _handle_dbapi_exception_noconnection
    util.raise_from_cause(sqlalchemy_exception, exc_info)
  File "/usr/local/lib/python2.7/site-packages/sqlalchemy/util/compat.py", line 383, in raise_from_cause
    reraise(type(exception), exception, tb=exc_tb, cause=cause)
  File "/usr/local/lib/python2.7/site-packages/sqlalchemy/engine/base.py", line 2262, in _wrap_pool_connect
    return fn()
  File "/usr/local/lib/python2.7/site-packages/sqlalchemy/pool/base.py", line 354, in connect
    return _ConnectionFairy._checkout(self)
  File "/usr/local/lib/python2.7/site-packages/sqlalchemy/pool/base.py", line 751, in _checkout
    fairy = _ConnectionRecord.checkout(pool)
  File "/usr/local/lib/python2.7/site-packages/sqlalchemy/pool/base.py", line 483, in checkout
    rec = pool._do_get()
  File "/usr/local/lib/python2.7/site-packages/sqlalchemy/pool/impl.py", line 138, in _do_get
    self._dec_overflow()
  File "/usr/local/lib/python2.7/site-packages/sqlalchemy/util/langhelpers.py", line 68, in __exit__
    compat.reraise(exc_type, exc_value, exc_tb)
  File "/usr/local/lib/python2.7/site-packages/sqlalchemy/pool/impl.py", line 135, in _do_get
    return self._create_connection()
  File "/usr/local/lib/python2.7/site-packages/sqlalchemy/pool/base.py", line 299, in _create_connection
    return _ConnectionRecord(self)
  File "/usr/local/lib/python2.7/site-packages/sqlalchemy/pool/base.py", line 428, in __init__
    self.__connect(first_connect_check=True)
  File "/usr/local/lib/python2.7/site-packages/sqlalchemy/pool/base.py", line 630, in __connect
    connection = pool._invoke_creator(self)
  File "/usr/local/lib/python2.7/site-packages/sqlalchemy/engine/strategies.py", line 114, in connect
    return dialect.connect(*cargs, **cparams)
  File "/usr/local/lib/python2.7/site-packages/sqlalchemy/engine/default.py", line 453, in connect
    return self.dbapi.connect(*cargs, **cparams)
  File "/usr/local/lib/python2.7/site-packages/psycopg2/__init__.py", line 130, in connect
    conn = _connect(dsn, connection_factory=connection_factory, **kwasync)
OperationalError: (psycopg2.OperationalError) could not translate host name "ec2-184-72-238-22.compute-1.amazonaws.com" to address: nodename nor servname provided, or not known

(Background on this error at: http://sqlalche.me/e/e3q8)
Traceback (most recent call last):
  File "/usr/local/lib/python2.7/site-packages/gunicorn/arbiter.py", line 515, in spawn_worker
    worker.init_process()
  File "/usr/local/lib/python2.7/site-packages/gunicorn/workers/base.py", line 122, in init_process
    self.load_wsgi()
  File "/usr/local/lib/python2.7/site-packages/gunicorn/workers/base.py", line 130, in load_wsgi
    self.wsgi = self.app.wsgi()
  File "/usr/local/lib/python2.7/site-packages/gunicorn/app/base.py", line 67, in wsgi
    self.callable = self.load()
  File "/usr/local/lib/python2.7/site-packages/psiturk/experiment_server.py", line 48, in load
    return util.import_app("psiturk.experiment:app")
  File "/usr/local/lib/python2.7/site-packages/gunicorn/util.py", line 357, in import_app
    __import__(module)
  File "/usr/local/lib/python2.7/site-packages/psiturk/experiment.py", line 89, in <module>
    init_db()
  File "/usr/local/lib/python2.7/site-packages/psiturk/db.py", line 39, in init_db
    Base.metadata.create_all(bind=engine)
  File "/usr/local/lib/python2.7/site-packages/sqlalchemy/sql/schema.py", line 4287, in create_all
    ddl.SchemaGenerator, self, checkfirst=checkfirst, tables=tables
  File "/usr/local/lib/python2.7/site-packages/sqlalchemy/engine/base.py", line 2032, in _run_visitor
    with self._optional_conn_ctx_manager(connection) as conn:
  File "/usr/local/Cellar/python@2/2.7.16/Frameworks/Python.framework/Versions/2.7/lib/python2.7/contextlib.py", line 17, in __enter__
    return self.gen.next()
  File "/usr/local/lib/python2.7/site-packages/sqlalchemy/engine/base.py", line 2024, in _optional_conn_ctx_manager
    with self._contextual_connect() as conn:
  File "/usr/local/lib/python2.7/site-packages/sqlalchemy/engine/base.py", line 2226, in _contextual_connect
    self._wrap_pool_connect(self.pool.connect, None),
  File "/usr/local/lib/python2.7/site-packages/sqlalchemy/engine/base.py", line 2266, in _wrap_pool_connect
    e, dialect, self
  File "/usr/local/lib/python2.7/site-packages/sqlalchemy/engine/base.py", line 1536, in _handle_dbapi_exception_noconnection
    util.raise_from_cause(sqlalchemy_exception, exc_info)
  File "/usr/local/lib/python2.7/site-packages/sqlalchemy/util/compat.py", line 383, in raise_from_cause
    reraise(type(exception), exception, tb=exc_tb, cause=cause)
  File "/usr/local/lib/python2.7/site-packages/sqlalchemy/engine/base.py", line 2262, in _wrap_pool_connect
    return fn()
  File "/usr/local/lib/python2.7/site-packages/sqlalchemy/pool/base.py", line 354, in connect
    return _ConnectionFairy._checkout(self)
  File "/usr/local/lib/python2.7/site-packages/sqlalchemy/pool/base.py", line 751, in _checkout
    fairy = _ConnectionRecord.checkout(pool)
  File "/usr/local/lib/python2.7/site-packages/sqlalchemy/pool/base.py", line 483, in checkout
    rec = pool._do_get()
  File "/usr/local/lib/python2.7/site-packages/sqlalchemy/pool/impl.py", line 138, in _do_get
    self._dec_overflow()
  File "/usr/local/lib/python2.7/site-packages/sqlalchemy/util/langhelpers.py", line 68, in __exit__
    compat.reraise(exc_type, exc_value, exc_tb)
  File "/usr/local/lib/python2.7/site-packages/sqlalchemy/pool/impl.py", line 135, in _do_get
    return self._create_connection()
  File "/usr/local/lib/python2.7/site-packages/sqlalchemy/pool/base.py", line 299, in _create_connection
    return _ConnectionRecord(self)
  File "/usr/local/lib/python2.7/site-packages/sqlalchemy/pool/base.py", line 428, in __init__
    self.__connect(first_connect_check=True)
  File "/usr/local/lib/python2.7/site-packages/sqlalchemy/pool/base.py", line 630, in __connect
    connection = pool._invoke_creator(self)
  File "/usr/local/lib/python2.7/site-packages/sqlalchemy/engine/strategies.py", line 114, in connect
    return dialect.connect(*cargs, **cparams)
  File "/usr/local/lib/python2.7/site-packages/sqlalchemy/engine/default.py", line 453, in connect
    return self.dbapi.connect(*cargs, **cparams)
  File "/usr/local/lib/python2.7/site-packages/psycopg2/__init__.py", line 130, in connect
    conn = _connect(dsn, connection_factory=connection_factory, **kwasync)
OperationalError: (psycopg2.OperationalError) could not translate host name "ec2-184-72-238-22.compute-1.amazonaws.com" to address: nodename nor servname provided, or not known

(Background on this error at: http://sqlalche.me/e/e3q8)
[2019-04-18 12:14:32 -0600] [1756] [CRITICAL] WORKER TIMEOUT (pid:1759)
[2019-04-18 12:14:39 -0600] [1925] [ERROR] Exception in worker process:
Traceback (most recent call last):
  File "/usr/local/lib/python2.7/site-packages/gunicorn/arbiter.py", line 515, in spawn_worker
    worker.init_process()
  File "/usr/local/lib/python2.7/site-packages/gunicorn/workers/base.py", line 122, in init_process
    self.load_wsgi()
  File "/usr/local/lib/python2.7/site-packages/gunicorn/workers/base.py", line 130, in load_wsgi
    self.wsgi = self.app.wsgi()
  File "/usr/local/lib/python2.7/site-packages/gunicorn/app/base.py", line 67, in wsgi
    self.callable = self.load()
  File "/usr/local/lib/python2.7/site-packages/psiturk/experiment_server.py", line 48, in load
    return util.import_app("psiturk.experiment:app")
  File "/usr/local/lib/python2.7/site-packages/gunicorn/util.py", line 357, in import_app
    __import__(module)
  File "/usr/local/lib/python2.7/site-packages/psiturk/experiment.py", line 89, in <module>
    init_db()
  File "/usr/local/lib/python2.7/site-packages/psiturk/db.py", line 39, in init_db
    Base.metadata.create_all(bind=engine)
  File "/usr/local/lib/python2.7/site-packages/sqlalchemy/sql/schema.py", line 4287, in create_all
    ddl.SchemaGenerator, self, checkfirst=checkfirst, tables=tables
  File "/usr/local/lib/python2.7/site-packages/sqlalchemy/engine/base.py", line 2032, in _run_visitor
    with self._optional_conn_ctx_manager(connection) as conn:
  File "/usr/local/Cellar/python@2/2.7.16/Frameworks/Python.framework/Versions/2.7/lib/python2.7/contextlib.py", line 17, in __enter__
    return self.gen.next()
  File "/usr/local/lib/python2.7/site-packages/sqlalchemy/engine/base.py", line 2024, in _optional_conn_ctx_manager
    with self._contextual_connect() as conn:
  File "/usr/local/lib/python2.7/site-packages/sqlalchemy/engine/base.py", line 2226, in _contextual_connect
    self._wrap_pool_connect(self.pool.connect, None),
  File "/usr/local/lib/python2.7/site-packages/sqlalchemy/engine/base.py", line 2266, in _wrap_pool_connect
    e, dialect, self
  File "/usr/local/lib/python2.7/site-packages/sqlalchemy/engine/base.py", line 1536, in _handle_dbapi_exception_noconnection
    util.raise_from_cause(sqlalchemy_exception, exc_info)
  File "/usr/local/lib/python2.7/site-packages/sqlalchemy/util/compat.py", line 383, in raise_from_cause
    reraise(type(exception), exception, tb=exc_tb, cause=cause)
  File "/usr/local/lib/python2.7/site-packages/sqlalchemy/engine/base.py", line 2262, in _wrap_pool_connect
    return fn()
  File "/usr/local/lib/python2.7/site-packages/sqlalchemy/pool/base.py", line 354, in connect
    return _ConnectionFairy._checkout(self)
  File "/usr/local/lib/python2.7/site-packages/sqlalchemy/pool/base.py", line 751, in _checkout
    fairy = _ConnectionRecord.checkout(pool)
  File "/usr/local/lib/python2.7/site-packages/sqlalchemy/pool/base.py", line 483, in checkout
    rec = pool._do_get()
  File "/usr/local/lib/python2.7/site-packages/sqlalchemy/pool/impl.py", line 138, in _do_get
    self._dec_overflow()
  File "/usr/local/lib/python2.7/site-packages/sqlalchemy/util/langhelpers.py", line 68, in __exit__
    compat.reraise(exc_type, exc_value, exc_tb)
  File "/usr/local/lib/python2.7/site-packages/sqlalchemy/pool/impl.py", line 135, in _do_get
    return self._create_connection()
  File "/usr/local/lib/python2.7/site-packages/sqlalchemy/pool/base.py", line 299, in _create_connection
    return _ConnectionRecord(self)
  File "/usr/local/lib/python2.7/site-packages/sqlalchemy/pool/base.py", line 428, in __init__
    self.__connect(first_connect_check=True)
  File "/usr/local/lib/python2.7/site-packages/sqlalchemy/pool/base.py", line 630, in __connect
    connection = pool._invoke_creator(self)
  File "/usr/local/lib/python2.7/site-packages/sqlalchemy/engine/strategies.py", line 114, in connect
    return dialect.connect(*cargs, **cparams)
  File "/usr/local/lib/python2.7/site-packages/sqlalchemy/engine/default.py", line 453, in connect
    return self.dbapi.connect(*cargs, **cparams)
  File "/usr/local/lib/python2.7/site-packages/psycopg2/__init__.py", line 130, in connect
    conn = _connect(dsn, connection_factory=connection_factory, **kwasync)
OperationalError: (psycopg2.OperationalError) could not translate host name "ec2-184-72-238-22.compute-1.amazonaws.com" to address: nodename nor servname provided, or not known

(Background on this error at: http://sqlalche.me/e/e3q8)
Traceback (most recent call last):
  File "/usr/local/lib/python2.7/site-packages/gunicorn/arbiter.py", line 515, in spawn_worker
    worker.init_process()
  File "/usr/local/lib/python2.7/site-packages/gunicorn/workers/base.py", line 122, in init_process
    self.load_wsgi()
  File "/usr/local/lib/python2.7/site-packages/gunicorn/workers/base.py", line 130, in load_wsgi
    self.wsgi = self.app.wsgi()
  File "/usr/local/lib/python2.7/site-packages/gunicorn/app/base.py", line 67, in wsgi
    self.callable = self.load()
  File "/usr/local/lib/python2.7/site-packages/psiturk/experiment_server.py", line 48, in load
    return util.import_app("psiturk.experiment:app")
  File "/usr/local/lib/python2.7/site-packages/gunicorn/util.py", line 357, in import_app
    __import__(module)
  File "/usr/local/lib/python2.7/site-packages/psiturk/experiment.py", line 89, in <module>
    init_db()
  File "/usr/local/lib/python2.7/site-packages/psiturk/db.py", line 39, in init_db
    Base.metadata.create_all(bind=engine)
  File "/usr/local/lib/python2.7/site-packages/sqlalchemy/sql/schema.py", line 4287, in create_all
    ddl.SchemaGenerator, self, checkfirst=checkfirst, tables=tables
  File "/usr/local/lib/python2.7/site-packages/sqlalchemy/engine/base.py", line 2032, in _run_visitor
    with self._optional_conn_ctx_manager(connection) as conn:
  File "/usr/local/Cellar/python@2/2.7.16/Frameworks/Python.framework/Versions/2.7/lib/python2.7/contextlib.py", line 17, in __enter__
    return self.gen.next()
  File "/usr/local/lib/python2.7/site-packages/sqlalchemy/engine/base.py", line 2024, in _optional_conn_ctx_manager
    with self._contextual_connect() as conn:
  File "/usr/local/lib/python2.7/site-packages/sqlalchemy/engine/base.py", line 2226, in _contextual_connect
    self._wrap_pool_connect(self.pool.connect, None),
  File "/usr/local/lib/python2.7/site-packages/sqlalchemy/engine/base.py", line 2266, in _wrap_pool_connect
    e, dialect, self
  File "/usr/local/lib/python2.7/site-packages/sqlalchemy/engine/base.py", line 1536, in _handle_dbapi_exception_noconnection
    util.raise_from_cause(sqlalchemy_exception, exc_info)
  File "/usr/local/lib/python2.7/site-packages/sqlalchemy/util/compat.py", line 383, in raise_from_cause
    reraise(type(exception), exception, tb=exc_tb, cause=cause)
  File "/usr/local/lib/python2.7/site-packages/sqlalchemy/engine/base.py", line 2262, in _wrap_pool_connect
    return fn()
  File "/usr/local/lib/python2.7/site-packages/sqlalchemy/pool/base.py", line 354, in connect
    return _ConnectionFairy._checkout(self)
  File "/usr/local/lib/python2.7/site-packages/sqlalchemy/pool/base.py", line 751, in _checkout
    fairy = _ConnectionRecord.checkout(pool)
  File "/usr/local/lib/python2.7/site-packages/sqlalchemy/pool/base.py", line 483, in checkout
    rec = pool._do_get()
  File "/usr/local/lib/python2.7/site-packages/sqlalchemy/pool/impl.py", line 138, in _do_get
    self._dec_overflow()
  File "/usr/local/lib/python2.7/site-packages/sqlalchemy/util/langhelpers.py", line 68, in __exit__
    compat.reraise(exc_type, exc_value, exc_tb)
  File "/usr/local/lib/python2.7/site-packages/sqlalchemy/pool/impl.py", line 135, in _do_get
    return self._create_connection()
  File "/usr/local/lib/python2.7/site-packages/sqlalchemy/pool/base.py", line 299, in _create_connection
    return _ConnectionRecord(self)
  File "/usr/local/lib/python2.7/site-packages/sqlalchemy/pool/base.py", line 428, in __init__
    self.__connect(first_connect_check=True)
  File "/usr/local/lib/python2.7/site-packages/sqlalchemy/pool/base.py", line 630, in __connect
    connection = pool._invoke_creator(self)
  File "/usr/local/lib/python2.7/site-packages/sqlalchemy/engine/strategies.py", line 114, in connect
    return dialect.connect(*cargs, **cparams)
  File "/usr/local/lib/python2.7/site-packages/sqlalchemy/engine/default.py", line 453, in connect
    return self.dbapi.connect(*cargs, **cparams)
  File "/usr/local/lib/python2.7/site-packages/psycopg2/__init__.py", line 130, in connect
    conn = _connect(dsn, connection_factory=connection_factory, **kwasync)
OperationalError: (psycopg2.OperationalError) could not translate host name "ec2-184-72-238-22.compute-1.amazonaws.com" to address: nodename nor servname provided, or not known

(Background on this error at: http://sqlalche.me/e/e3q8)
[2019-04-18 12:26:10 -0600] [1978] [CRITICAL] WORKER TIMEOUT (pid:1981)
[2019-04-18 12:26:13 -0600] [2071] [ERROR] Exception in worker process:
Traceback (most recent call last):
  File "/usr/local/lib/python2.7/site-packages/gunicorn/arbiter.py", line 515, in spawn_worker
    worker.init_process()
  File "/usr/local/lib/python2.7/site-packages/gunicorn/workers/base.py", line 122, in init_process
    self.load_wsgi()
  File "/usr/local/lib/python2.7/site-packages/gunicorn/workers/base.py", line 130, in load_wsgi
    self.wsgi = self.app.wsgi()
  File "/usr/local/lib/python2.7/site-packages/gunicorn/app/base.py", line 67, in wsgi
    self.callable = self.load()
  File "/usr/local/lib/python2.7/site-packages/psiturk/experiment_server.py", line 48, in load
    return util.import_app("psiturk.experiment:app")
  File "/usr/local/lib/python2.7/site-packages/gunicorn/util.py", line 357, in import_app
    __import__(module)
  File "/usr/local/lib/python2.7/site-packages/psiturk/experiment.py", line 89, in <module>
    init_db()
  File "/usr/local/lib/python2.7/site-packages/psiturk/db.py", line 39, in init_db
    Base.metadata.create_all(bind=engine)
  File "/usr/local/lib/python2.7/site-packages/sqlalchemy/sql/schema.py", line 4287, in create_all
    ddl.SchemaGenerator, self, checkfirst=checkfirst, tables=tables
  File "/usr/local/lib/python2.7/site-packages/sqlalchemy/engine/base.py", line 2032, in _run_visitor
    with self._optional_conn_ctx_manager(connection) as conn:
  File "/usr/local/Cellar/python@2/2.7.16/Frameworks/Python.framework/Versions/2.7/lib/python2.7/contextlib.py", line 17, in __enter__
    return self.gen.next()
  File "/usr/local/lib/python2.7/site-packages/sqlalchemy/engine/base.py", line 2024, in _optional_conn_ctx_manager
    with self._contextual_connect() as conn:
  File "/usr/local/lib/python2.7/site-packages/sqlalchemy/engine/base.py", line 2226, in _contextual_connect
    self._wrap_pool_connect(self.pool.connect, None),
  File "/usr/local/lib/python2.7/site-packages/sqlalchemy/engine/base.py", line 2266, in _wrap_pool_connect
    e, dialect, self
  File "/usr/local/lib/python2.7/site-packages/sqlalchemy/engine/base.py", line 1536, in _handle_dbapi_exception_noconnection
    util.raise_from_cause(sqlalchemy_exception, exc_info)
  File "/usr/local/lib/python2.7/site-packages/sqlalchemy/util/compat.py", line 383, in raise_from_cause
    reraise(type(exception), exception, tb=exc_tb, cause=cause)
  File "/usr/local/lib/python2.7/site-packages/sqlalchemy/engine/base.py", line 2262, in _wrap_pool_connect
    return fn()
  File "/usr/local/lib/python2.7/site-packages/sqlalchemy/pool/base.py", line 354, in connect
    return _ConnectionFairy._checkout(self)
  File "/usr/local/lib/python2.7/site-packages/sqlalchemy/pool/base.py", line 751, in _checkout
    fairy = _ConnectionRecord.checkout(pool)
  File "/usr/local/lib/python2.7/site-packages/sqlalchemy/pool/base.py", line 483, in checkout
    rec = pool._do_get()
  File "/usr/local/lib/python2.7/site-packages/sqlalchemy/pool/impl.py", line 138, in _do_get
    self._dec_overflow()
  File "/usr/local/lib/python2.7/site-packages/sqlalchemy/util/langhelpers.py", line 68, in __exit__
    compat.reraise(exc_type, exc_value, exc_tb)
  File "/usr/local/lib/python2.7/site-packages/sqlalchemy/pool/impl.py", line 135, in _do_get
    return self._create_connection()
  File "/usr/local/lib/python2.7/site-packages/sqlalchemy/pool/base.py", line 299, in _create_connection
    return _ConnectionRecord(self)
  File "/usr/local/lib/python2.7/site-packages/sqlalchemy/pool/base.py", line 428, in __init__
    self.__connect(first_connect_check=True)
  File "/usr/local/lib/python2.7/site-packages/sqlalchemy/pool/base.py", line 630, in __connect
    connection = pool._invoke_creator(self)
  File "/usr/local/lib/python2.7/site-packages/sqlalchemy/engine/strategies.py", line 114, in connect
    return dialect.connect(*cargs, **cparams)
  File "/usr/local/lib/python2.7/site-packages/sqlalchemy/engine/default.py", line 453, in connect
    return self.dbapi.connect(*cargs, **cparams)
  File "/usr/local/lib/python2.7/site-packages/psycopg2/__init__.py", line 130, in connect
    conn = _connect(dsn, connection_factory=connection_factory, **kwasync)
OperationalError: (psycopg2.OperationalError) could not translate host name "ec2-184-72-238-22.compute-1.amazonaws.com" to address: nodename nor servname provided, or not known

(Background on this error at: http://sqlalche.me/e/e3q8)
Traceback (most recent call last):
  File "/usr/local/lib/python2.7/site-packages/gunicorn/arbiter.py", line 515, in spawn_worker
    worker.init_process()
  File "/usr/local/lib/python2.7/site-packages/gunicorn/workers/base.py", line 122, in init_process
    self.load_wsgi()
  File "/usr/local/lib/python2.7/site-packages/gunicorn/workers/base.py", line 130, in load_wsgi
    self.wsgi = self.app.wsgi()
  File "/usr/local/lib/python2.7/site-packages/gunicorn/app/base.py", line 67, in wsgi
    self.callable = self.load()
  File "/usr/local/lib/python2.7/site-packages/psiturk/experiment_server.py", line 48, in load
    return util.import_app("psiturk.experiment:app")
  File "/usr/local/lib/python2.7/site-packages/gunicorn/util.py", line 357, in import_app
    __import__(module)
  File "/usr/local/lib/python2.7/site-packages/psiturk/experiment.py", line 89, in <module>
    init_db()
  File "/usr/local/lib/python2.7/site-packages/psiturk/db.py", line 39, in init_db
    Base.metadata.create_all(bind=engine)
  File "/usr/local/lib/python2.7/site-packages/sqlalchemy/sql/schema.py", line 4287, in create_all
    ddl.SchemaGenerator, self, checkfirst=checkfirst, tables=tables
  File "/usr/local/lib/python2.7/site-packages/sqlalchemy/engine/base.py", line 2032, in _run_visitor
    with self._optional_conn_ctx_manager(connection) as conn:
  File "/usr/local/Cellar/python@2/2.7.16/Frameworks/Python.framework/Versions/2.7/lib/python2.7/contextlib.py", line 17, in __enter__
    return self.gen.next()
  File "/usr/local/lib/python2.7/site-packages/sqlalchemy/engine/base.py", line 2024, in _optional_conn_ctx_manager
    with self._contextual_connect() as conn:
  File "/usr/local/lib/python2.7/site-packages/sqlalchemy/engine/base.py", line 2226, in _contextual_connect
    self._wrap_pool_connect(self.pool.connect, None),
  File "/usr/local/lib/python2.7/site-packages/sqlalchemy/engine/base.py", line 2266, in _wrap_pool_connect
    e, dialect, self
  File "/usr/local/lib/python2.7/site-packages/sqlalchemy/engine/base.py", line 1536, in _handle_dbapi_exception_noconnection
    util.raise_from_cause(sqlalchemy_exception, exc_info)
  File "/usr/local/lib/python2.7/site-packages/sqlalchemy/util/compat.py", line 383, in raise_from_cause
    reraise(type(exception), exception, tb=exc_tb, cause=cause)
  File "/usr/local/lib/python2.7/site-packages/sqlalchemy/engine/base.py", line 2262, in _wrap_pool_connect
    return fn()
  File "/usr/local/lib/python2.7/site-packages/sqlalchemy/pool/base.py", line 354, in connect
    return _ConnectionFairy._checkout(self)
  File "/usr/local/lib/python2.7/site-packages/sqlalchemy/pool/base.py", line 751, in _checkout
    fairy = _ConnectionRecord.checkout(pool)
  File "/usr/local/lib/python2.7/site-packages/sqlalchemy/pool/base.py", line 483, in checkout
    rec = pool._do_get()
  File "/usr/local/lib/python2.7/site-packages/sqlalchemy/pool/impl.py", line 138, in _do_get
    self._dec_overflow()
  File "/usr/local/lib/python2.7/site-packages/sqlalchemy/util/langhelpers.py", line 68, in __exit__
    compat.reraise(exc_type, exc_value, exc_tb)
  File "/usr/local/lib/python2.7/site-packages/sqlalchemy/pool/impl.py", line 135, in _do_get
    return self._create_connection()
  File "/usr/local/lib/python2.7/site-packages/sqlalchemy/pool/base.py", line 299, in _create_connection
    return _ConnectionRecord(self)
  File "/usr/local/lib/python2.7/site-packages/sqlalchemy/pool/base.py", line 428, in __init__
    self.__connect(first_connect_check=True)
  File "/usr/local/lib/python2.7/site-packages/sqlalchemy/pool/base.py", line 630, in __connect
    connection = pool._invoke_creator(self)
  File "/usr/local/lib/python2.7/site-packages/sqlalchemy/engine/strategies.py", line 114, in connect
    return dialect.connect(*cargs, **cparams)
  File "/usr/local/lib/python2.7/site-packages/sqlalchemy/engine/default.py", line 453, in connect
    return self.dbapi.connect(*cargs, **cparams)
  File "/usr/local/lib/python2.7/site-packages/psycopg2/__init__.py", line 130, in connect
    conn = _connect(dsn, connection_factory=connection_factory, **kwasync)
OperationalError: (psycopg2.OperationalError) could not translate host name "ec2-184-72-238-22.compute-1.amazonaws.com" to address: nodename nor servname provided, or not known

(Background on this error at: http://sqlalche.me/e/e3q8)
[2019-04-18 12:31:32,799] ERROR in app: Exception on /undefined [GET]
Traceback (most recent call last):
  File "/usr/local/lib/python2.7/site-packages/flask/app.py", line 1982, in wsgi_app
    response = self.full_dispatch_request()
  File "/usr/local/lib/python2.7/site-packages/flask/app.py", line 1614, in full_dispatch_request
    rv = self.handle_user_exception(e)
  File "/usr/local/lib/python2.7/site-packages/flask/app.py", line 1517, in handle_user_exception
    reraise(exc_type, exc_value, tb)
  File "/usr/local/lib/python2.7/site-packages/flask/app.py", line 1612, in full_dispatch_request
    rv = self.dispatch_request()
  File "/usr/local/lib/python2.7/site-packages/flask/app.py", line 1598, in dispatch_request
    return self.view_functions[rule.endpoint](**req.view_args)
  File "/usr/local/lib/python2.7/site-packages/psiturk/experiment.py", line 731, in regularpage
    return render_template(pagename)
  File "/usr/local/lib/python2.7/site-packages/flask/templating.py", line 133, in render_template
    return _render(ctx.app.jinja_env.get_or_select_template(template_name_or_list),
  File "/usr/local/lib/python2.7/site-packages/jinja2/environment.py", line 869, in get_or_select_template
    return self.get_template(template_name_or_list, parent, globals)
  File "/usr/local/lib/python2.7/site-packages/jinja2/environment.py", line 830, in get_template
    return self._load_template(name, self.make_globals(globals))
  File "/usr/local/lib/python2.7/site-packages/jinja2/environment.py", line 804, in _load_template
    template = self.loader.load(self, name, globals)
  File "/usr/local/lib/python2.7/site-packages/jinja2/loaders.py", line 113, in load
    source, filename, uptodate = self.get_source(environment, name)
  File "/usr/local/lib/python2.7/site-packages/flask/templating.py", line 57, in get_source
    return self._get_source_fast(environment, template)
  File "/usr/local/lib/python2.7/site-packages/flask/templating.py", line 85, in _get_source_fast
    raise TemplateNotFound(template)
TemplateNotFound: undefined
[2019-04-18 13:17:26,523] ERROR in app: Exception on /undefined [GET]
Traceback (most recent call last):
  File "/usr/local/lib/python2.7/site-packages/flask/app.py", line 1982, in wsgi_app
    response = self.full_dispatch_request()
  File "/usr/local/lib/python2.7/site-packages/flask/app.py", line 1614, in full_dispatch_request
    rv = self.handle_user_exception(e)
  File "/usr/local/lib/python2.7/site-packages/flask/app.py", line 1517, in handle_user_exception
    reraise(exc_type, exc_value, tb)
  File "/usr/local/lib/python2.7/site-packages/flask/app.py", line 1612, in full_dispatch_request
    rv = self.dispatch_request()
  File "/usr/local/lib/python2.7/site-packages/flask/app.py", line 1598, in dispatch_request
    return self.view_functions[rule.endpoint](**req.view_args)
  File "/usr/local/lib/python2.7/site-packages/psiturk/experiment.py", line 731, in regularpage
    return render_template(pagename)
  File "/usr/local/lib/python2.7/site-packages/flask/templating.py", line 133, in render_template
    return _render(ctx.app.jinja_env.get_or_select_template(template_name_or_list),
  File "/usr/local/lib/python2.7/site-packages/jinja2/environment.py", line 869, in get_or_select_template
    return self.get_template(template_name_or_list, parent, globals)
  File "/usr/local/lib/python2.7/site-packages/jinja2/environment.py", line 830, in get_template
    return self._load_template(name, self.make_globals(globals))
  File "/usr/local/lib/python2.7/site-packages/jinja2/environment.py", line 804, in _load_template
    template = self.loader.load(self, name, globals)
  File "/usr/local/lib/python2.7/site-packages/jinja2/loaders.py", line 113, in load
    source, filename, uptodate = self.get_source(environment, name)
  File "/usr/local/lib/python2.7/site-packages/flask/templating.py", line 57, in get_source
    return self._get_source_fast(environment, template)
  File "/usr/local/lib/python2.7/site-packages/flask/templating.py", line 85, in _get_source_fast
    raise TemplateNotFound(template)
TemplateNotFound: undefined
[2019-04-18 17:04:17 -0600] [1343] [CRITICAL] WORKER TIMEOUT (pid:1346)
[2019-04-18 17:04:50 -0600] [1343] [CRITICAL] WORKER TIMEOUT (pid:1360)
[2019-04-18 17:16:47 -0600] [1343] [CRITICAL] WORKER TIMEOUT (pid:1361)
[2019-04-18 17:16:49 -0600] [1386] [ERROR] Exception in worker process:
Traceback (most recent call last):
  File "/usr/local/lib/python2.7/site-packages/gunicorn/arbiter.py", line 515, in spawn_worker
    worker.init_process()
  File "/usr/local/lib/python2.7/site-packages/gunicorn/workers/base.py", line 122, in init_process
    self.load_wsgi()
  File "/usr/local/lib/python2.7/site-packages/gunicorn/workers/base.py", line 130, in load_wsgi
    self.wsgi = self.app.wsgi()
  File "/usr/local/lib/python2.7/site-packages/gunicorn/app/base.py", line 67, in wsgi
    self.callable = self.load()
  File "/usr/local/lib/python2.7/site-packages/psiturk/experiment_server.py", line 48, in load
    return util.import_app("psiturk.experiment:app")
  File "/usr/local/lib/python2.7/site-packages/gunicorn/util.py", line 357, in import_app
    __import__(module)
  File "/usr/local/lib/python2.7/site-packages/psiturk/experiment.py", line 89, in <module>
    init_db()
  File "/usr/local/lib/python2.7/site-packages/psiturk/db.py", line 39, in init_db
    Base.metadata.create_all(bind=engine)
  File "/usr/local/lib/python2.7/site-packages/sqlalchemy/sql/schema.py", line 4287, in create_all
    ddl.SchemaGenerator, self, checkfirst=checkfirst, tables=tables
  File "/usr/local/lib/python2.7/site-packages/sqlalchemy/engine/base.py", line 2032, in _run_visitor
    with self._optional_conn_ctx_manager(connection) as conn:
  File "/usr/local/Cellar/python@2/2.7.16/Frameworks/Python.framework/Versions/2.7/lib/python2.7/contextlib.py", line 17, in __enter__
    return self.gen.next()
  File "/usr/local/lib/python2.7/site-packages/sqlalchemy/engine/base.py", line 2024, in _optional_conn_ctx_manager
    with self._contextual_connect() as conn:
  File "/usr/local/lib/python2.7/site-packages/sqlalchemy/engine/base.py", line 2226, in _contextual_connect
    self._wrap_pool_connect(self.pool.connect, None),
  File "/usr/local/lib/python2.7/site-packages/sqlalchemy/engine/base.py", line 2266, in _wrap_pool_connect
    e, dialect, self
  File "/usr/local/lib/python2.7/site-packages/sqlalchemy/engine/base.py", line 1536, in _handle_dbapi_exception_noconnection
    util.raise_from_cause(sqlalchemy_exception, exc_info)
  File "/usr/local/lib/python2.7/site-packages/sqlalchemy/util/compat.py", line 383, in raise_from_cause
    reraise(type(exception), exception, tb=exc_tb, cause=cause)
  File "/usr/local/lib/python2.7/site-packages/sqlalchemy/engine/base.py", line 2262, in _wrap_pool_connect
    return fn()
  File "/usr/local/lib/python2.7/site-packages/sqlalchemy/pool/base.py", line 354, in connect
    return _ConnectionFairy._checkout(self)
  File "/usr/local/lib/python2.7/site-packages/sqlalchemy/pool/base.py", line 751, in _checkout
    fairy = _ConnectionRecord.checkout(pool)
  File "/usr/local/lib/python2.7/site-packages/sqlalchemy/pool/base.py", line 483, in checkout
    rec = pool._do_get()
  File "/usr/local/lib/python2.7/site-packages/sqlalchemy/pool/impl.py", line 138, in _do_get
    self._dec_overflow()
  File "/usr/local/lib/python2.7/site-packages/sqlalchemy/util/langhelpers.py", line 68, in __exit__
    compat.reraise(exc_type, exc_value, exc_tb)
  File "/usr/local/lib/python2.7/site-packages/sqlalchemy/pool/impl.py", line 135, in _do_get
    return self._create_connection()
  File "/usr/local/lib/python2.7/site-packages/sqlalchemy/pool/base.py", line 299, in _create_connection
    return _ConnectionRecord(self)
  File "/usr/local/lib/python2.7/site-packages/sqlalchemy/pool/base.py", line 428, in __init__
    self.__connect(first_connect_check=True)
  File "/usr/local/lib/python2.7/site-packages/sqlalchemy/pool/base.py", line 630, in __connect
    connection = pool._invoke_creator(self)
  File "/usr/local/lib/python2.7/site-packages/sqlalchemy/engine/strategies.py", line 114, in connect
    return dialect.connect(*cargs, **cparams)
  File "/usr/local/lib/python2.7/site-packages/sqlalchemy/engine/default.py", line 453, in connect
    return self.dbapi.connect(*cargs, **cparams)
  File "/usr/local/lib/python2.7/site-packages/psycopg2/__init__.py", line 130, in connect
    conn = _connect(dsn, connection_factory=connection_factory, **kwasync)
OperationalError: (psycopg2.OperationalError) could not translate host name "ec2-184-72-238-22.compute-1.amazonaws.com" to address: nodename nor servname provided, or not known

(Background on this error at: http://sqlalche.me/e/e3q8)
Traceback (most recent call last):
  File "/usr/local/lib/python2.7/site-packages/gunicorn/arbiter.py", line 515, in spawn_worker
    worker.init_process()
  File "/usr/local/lib/python2.7/site-packages/gunicorn/workers/base.py", line 122, in init_process
    self.load_wsgi()
  File "/usr/local/lib/python2.7/site-packages/gunicorn/workers/base.py", line 130, in load_wsgi
    self.wsgi = self.app.wsgi()
  File "/usr/local/lib/python2.7/site-packages/gunicorn/app/base.py", line 67, in wsgi
    self.callable = self.load()
  File "/usr/local/lib/python2.7/site-packages/psiturk/experiment_server.py", line 48, in load
    return util.import_app("psiturk.experiment:app")
  File "/usr/local/lib/python2.7/site-packages/gunicorn/util.py", line 357, in import_app
    __import__(module)
  File "/usr/local/lib/python2.7/site-packages/psiturk/experiment.py", line 89, in <module>
    init_db()
  File "/usr/local/lib/python2.7/site-packages/psiturk/db.py", line 39, in init_db
    Base.metadata.create_all(bind=engine)
  File "/usr/local/lib/python2.7/site-packages/sqlalchemy/sql/schema.py", line 4287, in create_all
    ddl.SchemaGenerator, self, checkfirst=checkfirst, tables=tables
  File "/usr/local/lib/python2.7/site-packages/sqlalchemy/engine/base.py", line 2032, in _run_visitor
    with self._optional_conn_ctx_manager(connection) as conn:
  File "/usr/local/Cellar/python@2/2.7.16/Frameworks/Python.framework/Versions/2.7/lib/python2.7/contextlib.py", line 17, in __enter__
    return self.gen.next()
  File "/usr/local/lib/python2.7/site-packages/sqlalchemy/engine/base.py", line 2024, in _optional_conn_ctx_manager
    with self._contextual_connect() as conn:
  File "/usr/local/lib/python2.7/site-packages/sqlalchemy/engine/base.py", line 2226, in _contextual_connect
    self._wrap_pool_connect(self.pool.connect, None),
  File "/usr/local/lib/python2.7/site-packages/sqlalchemy/engine/base.py", line 2266, in _wrap_pool_connect
    e, dialect, self
  File "/usr/local/lib/python2.7/site-packages/sqlalchemy/engine/base.py", line 1536, in _handle_dbapi_exception_noconnection
    util.raise_from_cause(sqlalchemy_exception, exc_info)
  File "/usr/local/lib/python2.7/site-packages/sqlalchemy/util/compat.py", line 383, in raise_from_cause
    reraise(type(exception), exception, tb=exc_tb, cause=cause)
  File "/usr/local/lib/python2.7/site-packages/sqlalchemy/engine/base.py", line 2262, in _wrap_pool_connect
    return fn()
  File "/usr/local/lib/python2.7/site-packages/sqlalchemy/pool/base.py", line 354, in connect
    return _ConnectionFairy._checkout(self)
  File "/usr/local/lib/python2.7/site-packages/sqlalchemy/pool/base.py", line 751, in _checkout
    fairy = _ConnectionRecord.checkout(pool)
  File "/usr/local/lib/python2.7/site-packages/sqlalchemy/pool/base.py", line 483, in checkout
    rec = pool._do_get()
  File "/usr/local/lib/python2.7/site-packages/sqlalchemy/pool/impl.py", line 138, in _do_get
    self._dec_overflow()
  File "/usr/local/lib/python2.7/site-packages/sqlalchemy/util/langhelpers.py", line 68, in __exit__
    compat.reraise(exc_type, exc_value, exc_tb)
  File "/usr/local/lib/python2.7/site-packages/sqlalchemy/pool/impl.py", line 135, in _do_get
    return self._create_connection()
  File "/usr/local/lib/python2.7/site-packages/sqlalchemy/pool/base.py", line 299, in _create_connection
    return _ConnectionRecord(self)
  File "/usr/local/lib/python2.7/site-packages/sqlalchemy/pool/base.py", line 428, in __init__
    self.__connect(first_connect_check=True)
  File "/usr/local/lib/python2.7/site-packages/sqlalchemy/pool/base.py", line 630, in __connect
    connection = pool._invoke_creator(self)
  File "/usr/local/lib/python2.7/site-packages/sqlalchemy/engine/strategies.py", line 114, in connect
    return dialect.connect(*cargs, **cparams)
  File "/usr/local/lib/python2.7/site-packages/sqlalchemy/engine/default.py", line 453, in connect
    return self.dbapi.connect(*cargs, **cparams)
  File "/usr/local/lib/python2.7/site-packages/psycopg2/__init__.py", line 130, in connect
    conn = _connect(dsn, connection_factory=connection_factory, **kwasync)
OperationalError: (psycopg2.OperationalError) could not translate host name "ec2-184-72-238-22.compute-1.amazonaws.com" to address: nodename nor servname provided, or not known

(Background on this error at: http://sqlalche.me/e/e3q8)
[2019-04-19 11:09:13,472] ERROR in app: Exception on /tor.wager@colorado.edu [GET]
Traceback (most recent call last):
  File "/usr/local/lib/python2.7/site-packages/flask/app.py", line 1982, in wsgi_app
    response = self.full_dispatch_request()
  File "/usr/local/lib/python2.7/site-packages/flask/app.py", line 1614, in full_dispatch_request
    rv = self.handle_user_exception(e)
  File "/usr/local/lib/python2.7/site-packages/flask/app.py", line 1517, in handle_user_exception
    reraise(exc_type, exc_value, tb)
  File "/usr/local/lib/python2.7/site-packages/flask/app.py", line 1612, in full_dispatch_request
    rv = self.dispatch_request()
  File "/usr/local/lib/python2.7/site-packages/flask/app.py", line 1598, in dispatch_request
    return self.view_functions[rule.endpoint](**req.view_args)
  File "/usr/local/lib/python2.7/site-packages/psiturk/experiment.py", line 731, in regularpage
    return render_template(pagename)
  File "/usr/local/lib/python2.7/site-packages/flask/templating.py", line 133, in render_template
    return _render(ctx.app.jinja_env.get_or_select_template(template_name_or_list),
  File "/usr/local/lib/python2.7/site-packages/jinja2/environment.py", line 869, in get_or_select_template
    return self.get_template(template_name_or_list, parent, globals)
  File "/usr/local/lib/python2.7/site-packages/jinja2/environment.py", line 830, in get_template
    return self._load_template(name, self.make_globals(globals))
  File "/usr/local/lib/python2.7/site-packages/jinja2/environment.py", line 804, in _load_template
    template = self.loader.load(self, name, globals)
  File "/usr/local/lib/python2.7/site-packages/jinja2/loaders.py", line 113, in load
    source, filename, uptodate = self.get_source(environment, name)
  File "/usr/local/lib/python2.7/site-packages/flask/templating.py", line 57, in get_source
    return self._get_source_fast(environment, template)
  File "/usr/local/lib/python2.7/site-packages/flask/templating.py", line 85, in _get_source_fast
    raise TemplateNotFound(template)
TemplateNotFound: tor.wager@colorado.edu
[2019-04-19 11:14:19 -0600] [1781] [CRITICAL] WORKER TIMEOUT (pid:1784)
[2019-04-19 17:14:53 -0600] [2249] [CRITICAL] WORKER TIMEOUT (pid:2252)
[2019-04-19 17:14:58 -0600] [2332] [ERROR] Exception in worker process:
Traceback (most recent call last):
  File "/usr/local/lib/python2.7/site-packages/gunicorn/arbiter.py", line 515, in spawn_worker
    worker.init_process()
  File "/usr/local/lib/python2.7/site-packages/gunicorn/workers/base.py", line 122, in init_process
    self.load_wsgi()
  File "/usr/local/lib/python2.7/site-packages/gunicorn/workers/base.py", line 130, in load_wsgi
    self.wsgi = self.app.wsgi()
  File "/usr/local/lib/python2.7/site-packages/gunicorn/app/base.py", line 67, in wsgi
    self.callable = self.load()
  File "/usr/local/lib/python2.7/site-packages/psiturk/experiment_server.py", line 48, in load
    return util.import_app("psiturk.experiment:app")
  File "/usr/local/lib/python2.7/site-packages/gunicorn/util.py", line 357, in import_app
    __import__(module)
  File "/usr/local/lib/python2.7/site-packages/psiturk/experiment.py", line 89, in <module>
    init_db()
  File "/usr/local/lib/python2.7/site-packages/psiturk/db.py", line 39, in init_db
    Base.metadata.create_all(bind=engine)
  File "/usr/local/lib/python2.7/site-packages/sqlalchemy/sql/schema.py", line 4287, in create_all
    ddl.SchemaGenerator, self, checkfirst=checkfirst, tables=tables
  File "/usr/local/lib/python2.7/site-packages/sqlalchemy/engine/base.py", line 2032, in _run_visitor
    with self._optional_conn_ctx_manager(connection) as conn:
  File "/usr/local/Cellar/python@2/2.7.16/Frameworks/Python.framework/Versions/2.7/lib/python2.7/contextlib.py", line 17, in __enter__
    return self.gen.next()
  File "/usr/local/lib/python2.7/site-packages/sqlalchemy/engine/base.py", line 2024, in _optional_conn_ctx_manager
    with self._contextual_connect() as conn:
  File "/usr/local/lib/python2.7/site-packages/sqlalchemy/engine/base.py", line 2226, in _contextual_connect
    self._wrap_pool_connect(self.pool.connect, None),
  File "/usr/local/lib/python2.7/site-packages/sqlalchemy/engine/base.py", line 2266, in _wrap_pool_connect
    e, dialect, self
  File "/usr/local/lib/python2.7/site-packages/sqlalchemy/engine/base.py", line 1536, in _handle_dbapi_exception_noconnection
    util.raise_from_cause(sqlalchemy_exception, exc_info)
  File "/usr/local/lib/python2.7/site-packages/sqlalchemy/util/compat.py", line 383, in raise_from_cause
    reraise(type(exception), exception, tb=exc_tb, cause=cause)
  File "/usr/local/lib/python2.7/site-packages/sqlalchemy/engine/base.py", line 2262, in _wrap_pool_connect
    return fn()
  File "/usr/local/lib/python2.7/site-packages/sqlalchemy/pool/base.py", line 354, in connect
    return _ConnectionFairy._checkout(self)
  File "/usr/local/lib/python2.7/site-packages/sqlalchemy/pool/base.py", line 751, in _checkout
    fairy = _ConnectionRecord.checkout(pool)
  File "/usr/local/lib/python2.7/site-packages/sqlalchemy/pool/base.py", line 483, in checkout
    rec = pool._do_get()
  File "/usr/local/lib/python2.7/site-packages/sqlalchemy/pool/impl.py", line 138, in _do_get
    self._dec_overflow()
  File "/usr/local/lib/python2.7/site-packages/sqlalchemy/util/langhelpers.py", line 68, in __exit__
    compat.reraise(exc_type, exc_value, exc_tb)
  File "/usr/local/lib/python2.7/site-packages/sqlalchemy/pool/impl.py", line 135, in _do_get
    return self._create_connection()
  File "/usr/local/lib/python2.7/site-packages/sqlalchemy/pool/base.py", line 299, in _create_connection
    return _ConnectionRecord(self)
  File "/usr/local/lib/python2.7/site-packages/sqlalchemy/pool/base.py", line 428, in __init__
    self.__connect(first_connect_check=True)
  File "/usr/local/lib/python2.7/site-packages/sqlalchemy/pool/base.py", line 630, in __connect
    connection = pool._invoke_creator(self)
  File "/usr/local/lib/python2.7/site-packages/sqlalchemy/engine/strategies.py", line 114, in connect
    return dialect.connect(*cargs, **cparams)
  File "/usr/local/lib/python2.7/site-packages/sqlalchemy/engine/default.py", line 453, in connect
    return self.dbapi.connect(*cargs, **cparams)
  File "/usr/local/lib/python2.7/site-packages/psycopg2/__init__.py", line 130, in connect
    conn = _connect(dsn, connection_factory=connection_factory, **kwasync)
OperationalError: (psycopg2.OperationalError) could not translate host name "ec2-184-72-238-22.compute-1.amazonaws.com" to address: nodename nor servname provided, or not known

(Background on this error at: http://sqlalche.me/e/e3q8)
Traceback (most recent call last):
  File "/usr/local/lib/python2.7/site-packages/gunicorn/arbiter.py", line 515, in spawn_worker
    worker.init_process()
  File "/usr/local/lib/python2.7/site-packages/gunicorn/workers/base.py", line 122, in init_process
    self.load_wsgi()
  File "/usr/local/lib/python2.7/site-packages/gunicorn/workers/base.py", line 130, in load_wsgi
    self.wsgi = self.app.wsgi()
  File "/usr/local/lib/python2.7/site-packages/gunicorn/app/base.py", line 67, in wsgi
    self.callable = self.load()
  File "/usr/local/lib/python2.7/site-packages/psiturk/experiment_server.py", line 48, in load
    return util.import_app("psiturk.experiment:app")
  File "/usr/local/lib/python2.7/site-packages/gunicorn/util.py", line 357, in import_app
    __import__(module)
  File "/usr/local/lib/python2.7/site-packages/psiturk/experiment.py", line 89, in <module>
    init_db()
  File "/usr/local/lib/python2.7/site-packages/psiturk/db.py", line 39, in init_db
    Base.metadata.create_all(bind=engine)
  File "/usr/local/lib/python2.7/site-packages/sqlalchemy/sql/schema.py", line 4287, in create_all
    ddl.SchemaGenerator, self, checkfirst=checkfirst, tables=tables
  File "/usr/local/lib/python2.7/site-packages/sqlalchemy/engine/base.py", line 2032, in _run_visitor
    with self._optional_conn_ctx_manager(connection) as conn:
  File "/usr/local/Cellar/python@2/2.7.16/Frameworks/Python.framework/Versions/2.7/lib/python2.7/contextlib.py", line 17, in __enter__
    return self.gen.next()
  File "/usr/local/lib/python2.7/site-packages/sqlalchemy/engine/base.py", line 2024, in _optional_conn_ctx_manager
    with self._contextual_connect() as conn:
  File "/usr/local/lib/python2.7/site-packages/sqlalchemy/engine/base.py", line 2226, in _contextual_connect
    self._wrap_pool_connect(self.pool.connect, None),
  File "/usr/local/lib/python2.7/site-packages/sqlalchemy/engine/base.py", line 2266, in _wrap_pool_connect
    e, dialect, self
  File "/usr/local/lib/python2.7/site-packages/sqlalchemy/engine/base.py", line 1536, in _handle_dbapi_exception_noconnection
    util.raise_from_cause(sqlalchemy_exception, exc_info)
  File "/usr/local/lib/python2.7/site-packages/sqlalchemy/util/compat.py", line 383, in raise_from_cause
    reraise(type(exception), exception, tb=exc_tb, cause=cause)
  File "/usr/local/lib/python2.7/site-packages/sqlalchemy/engine/base.py", line 2262, in _wrap_pool_connect
    return fn()
  File "/usr/local/lib/python2.7/site-packages/sqlalchemy/pool/base.py", line 354, in connect
    return _ConnectionFairy._checkout(self)
  File "/usr/local/lib/python2.7/site-packages/sqlalchemy/pool/base.py", line 751, in _checkout
    fairy = _ConnectionRecord.checkout(pool)
  File "/usr/local/lib/python2.7/site-packages/sqlalchemy/pool/base.py", line 483, in checkout
    rec = pool._do_get()
  File "/usr/local/lib/python2.7/site-packages/sqlalchemy/pool/impl.py", line 138, in _do_get
    self._dec_overflow()
  File "/usr/local/lib/python2.7/site-packages/sqlalchemy/util/langhelpers.py", line 68, in __exit__
    compat.reraise(exc_type, exc_value, exc_tb)
  File "/usr/local/lib/python2.7/site-packages/sqlalchemy/pool/impl.py", line 135, in _do_get
    return self._create_connection()
  File "/usr/local/lib/python2.7/site-packages/sqlalchemy/pool/base.py", line 299, in _create_connection
    return _ConnectionRecord(self)
  File "/usr/local/lib/python2.7/site-packages/sqlalchemy/pool/base.py", line 428, in __init__
    self.__connect(first_connect_check=True)
  File "/usr/local/lib/python2.7/site-packages/sqlalchemy/pool/base.py", line 630, in __connect
    connection = pool._invoke_creator(self)
  File "/usr/local/lib/python2.7/site-packages/sqlalchemy/engine/strategies.py", line 114, in connect
    return dialect.connect(*cargs, **cparams)
  File "/usr/local/lib/python2.7/site-packages/sqlalchemy/engine/default.py", line 453, in connect
    return self.dbapi.connect(*cargs, **cparams)
  File "/usr/local/lib/python2.7/site-packages/psycopg2/__init__.py", line 130, in connect
    conn = _connect(dsn, connection_factory=connection_factory, **kwasync)
OperationalError: (psycopg2.OperationalError) could not translate host name "ec2-184-72-238-22.compute-1.amazonaws.com" to address: nodename nor servname provided, or not known

(Background on this error at: http://sqlalche.me/e/e3q8)
[2019-04-20 14:32:17,481] ERROR in app: Exception on /undefined [GET]
Traceback (most recent call last):
  File "/usr/local/lib/python2.7/site-packages/flask/app.py", line 1982, in wsgi_app
    response = self.full_dispatch_request()
  File "/usr/local/lib/python2.7/site-packages/flask/app.py", line 1614, in full_dispatch_request
    rv = self.handle_user_exception(e)
  File "/usr/local/lib/python2.7/site-packages/flask/app.py", line 1517, in handle_user_exception
    reraise(exc_type, exc_value, tb)
  File "/usr/local/lib/python2.7/site-packages/flask/app.py", line 1612, in full_dispatch_request
    rv = self.dispatch_request()
  File "/usr/local/lib/python2.7/site-packages/flask/app.py", line 1598, in dispatch_request
    return self.view_functions[rule.endpoint](**req.view_args)
  File "/usr/local/lib/python2.7/site-packages/psiturk/experiment.py", line 731, in regularpage
    return render_template(pagename)
  File "/usr/local/lib/python2.7/site-packages/flask/templating.py", line 133, in render_template
    return _render(ctx.app.jinja_env.get_or_select_template(template_name_or_list),
  File "/usr/local/lib/python2.7/site-packages/jinja2/environment.py", line 869, in get_or_select_template
    return self.get_template(template_name_or_list, parent, globals)
  File "/usr/local/lib/python2.7/site-packages/jinja2/environment.py", line 830, in get_template
    return self._load_template(name, self.make_globals(globals))
  File "/usr/local/lib/python2.7/site-packages/jinja2/environment.py", line 804, in _load_template
    template = self.loader.load(self, name, globals)
  File "/usr/local/lib/python2.7/site-packages/jinja2/loaders.py", line 113, in load
    source, filename, uptodate = self.get_source(environment, name)
  File "/usr/local/lib/python2.7/site-packages/flask/templating.py", line 57, in get_source
    return self._get_source_fast(environment, template)
  File "/usr/local/lib/python2.7/site-packages/flask/templating.py", line 85, in _get_source_fast
    raise TemplateNotFound(template)
TemplateNotFound: undefined
[2019-04-20 14:32:30,378] ERROR in app: Exception on /undefined [GET]
Traceback (most recent call last):
  File "/usr/local/lib/python2.7/site-packages/flask/app.py", line 1982, in wsgi_app
    response = self.full_dispatch_request()
  File "/usr/local/lib/python2.7/site-packages/flask/app.py", line 1614, in full_dispatch_request
    rv = self.handle_user_exception(e)
  File "/usr/local/lib/python2.7/site-packages/flask/app.py", line 1517, in handle_user_exception
    reraise(exc_type, exc_value, tb)
  File "/usr/local/lib/python2.7/site-packages/flask/app.py", line 1612, in full_dispatch_request
    rv = self.dispatch_request()
  File "/usr/local/lib/python2.7/site-packages/flask/app.py", line 1598, in dispatch_request
    return self.view_functions[rule.endpoint](**req.view_args)
  File "/usr/local/lib/python2.7/site-packages/psiturk/experiment.py", line 731, in regularpage
    return render_template(pagename)
  File "/usr/local/lib/python2.7/site-packages/flask/templating.py", line 133, in render_template
    return _render(ctx.app.jinja_env.get_or_select_template(template_name_or_list),
  File "/usr/local/lib/python2.7/site-packages/jinja2/environment.py", line 869, in get_or_select_template
    return self.get_template(template_name_or_list, parent, globals)
  File "/usr/local/lib/python2.7/site-packages/jinja2/environment.py", line 830, in get_template
    return self._load_template(name, self.make_globals(globals))
  File "/usr/local/lib/python2.7/site-packages/jinja2/environment.py", line 804, in _load_template
    template = self.loader.load(self, name, globals)
  File "/usr/local/lib/python2.7/site-packages/jinja2/loaders.py", line 113, in load
    source, filename, uptodate = self.get_source(environment, name)
  File "/usr/local/lib/python2.7/site-packages/flask/templating.py", line 57, in get_source
    return self._get_source_fast(environment, template)
  File "/usr/local/lib/python2.7/site-packages/flask/templating.py", line 85, in _get_source_fast
    raise TemplateNotFound(template)
TemplateNotFound: undefined
[2019-04-20 14:34:20,819] ERROR in app: Exception on /undefined [GET]
Traceback (most recent call last):
  File "/usr/local/lib/python2.7/site-packages/flask/app.py", line 1982, in wsgi_app
    response = self.full_dispatch_request()
  File "/usr/local/lib/python2.7/site-packages/flask/app.py", line 1614, in full_dispatch_request
    rv = self.handle_user_exception(e)
  File "/usr/local/lib/python2.7/site-packages/flask/app.py", line 1517, in handle_user_exception
    reraise(exc_type, exc_value, tb)
  File "/usr/local/lib/python2.7/site-packages/flask/app.py", line 1612, in full_dispatch_request
    rv = self.dispatch_request()
  File "/usr/local/lib/python2.7/site-packages/flask/app.py", line 1598, in dispatch_request
    return self.view_functions[rule.endpoint](**req.view_args)
  File "/usr/local/lib/python2.7/site-packages/psiturk/experiment.py", line 731, in regularpage
    return render_template(pagename)
  File "/usr/local/lib/python2.7/site-packages/flask/templating.py", line 133, in render_template
    return _render(ctx.app.jinja_env.get_or_select_template(template_name_or_list),
  File "/usr/local/lib/python2.7/site-packages/jinja2/environment.py", line 869, in get_or_select_template
    return self.get_template(template_name_or_list, parent, globals)
  File "/usr/local/lib/python2.7/site-packages/jinja2/environment.py", line 830, in get_template
    return self._load_template(name, self.make_globals(globals))
  File "/usr/local/lib/python2.7/site-packages/jinja2/environment.py", line 804, in _load_template
    template = self.loader.load(self, name, globals)
  File "/usr/local/lib/python2.7/site-packages/jinja2/loaders.py", line 113, in load
    source, filename, uptodate = self.get_source(environment, name)
  File "/usr/local/lib/python2.7/site-packages/flask/templating.py", line 57, in get_source
    return self._get_source_fast(environment, template)
  File "/usr/local/lib/python2.7/site-packages/flask/templating.py", line 85, in _get_source_fast
    raise TemplateNotFound(template)
TemplateNotFound: undefined
[2019-04-20 14:34:23,282] ERROR in app: Exception on /undefined [GET]
Traceback (most recent call last):
  File "/usr/local/lib/python2.7/site-packages/flask/app.py", line 1982, in wsgi_app
    response = self.full_dispatch_request()
  File "/usr/local/lib/python2.7/site-packages/flask/app.py", line 1614, in full_dispatch_request
    rv = self.handle_user_exception(e)
  File "/usr/local/lib/python2.7/site-packages/flask/app.py", line 1517, in handle_user_exception
    reraise(exc_type, exc_value, tb)
  File "/usr/local/lib/python2.7/site-packages/flask/app.py", line 1612, in full_dispatch_request
    rv = self.dispatch_request()
  File "/usr/local/lib/python2.7/site-packages/flask/app.py", line 1598, in dispatch_request
    return self.view_functions[rule.endpoint](**req.view_args)
  File "/usr/local/lib/python2.7/site-packages/psiturk/experiment.py", line 731, in regularpage
    return render_template(pagename)
  File "/usr/local/lib/python2.7/site-packages/flask/templating.py", line 133, in render_template
    return _render(ctx.app.jinja_env.get_or_select_template(template_name_or_list),
  File "/usr/local/lib/python2.7/site-packages/jinja2/environment.py", line 869, in get_or_select_template
    return self.get_template(template_name_or_list, parent, globals)
  File "/usr/local/lib/python2.7/site-packages/jinja2/environment.py", line 830, in get_template
    return self._load_template(name, self.make_globals(globals))
  File "/usr/local/lib/python2.7/site-packages/jinja2/environment.py", line 804, in _load_template
    template = self.loader.load(self, name, globals)
  File "/usr/local/lib/python2.7/site-packages/jinja2/loaders.py", line 113, in load
    source, filename, uptodate = self.get_source(environment, name)
  File "/usr/local/lib/python2.7/site-packages/flask/templating.py", line 57, in get_source
    return self._get_source_fast(environment, template)
  File "/usr/local/lib/python2.7/site-packages/flask/templating.py", line 85, in _get_source_fast
    raise TemplateNotFound(template)
TemplateNotFound: undefined
[2019-04-20 14:36:03,601] ERROR in app: Exception on /undefined [GET]
Traceback (most recent call last):
  File "/usr/local/lib/python2.7/site-packages/flask/app.py", line 1982, in wsgi_app
    response = self.full_dispatch_request()
  File "/usr/local/lib/python2.7/site-packages/flask/app.py", line 1614, in full_dispatch_request
    rv = self.handle_user_exception(e)
  File "/usr/local/lib/python2.7/site-packages/flask/app.py", line 1517, in handle_user_exception
    reraise(exc_type, exc_value, tb)
  File "/usr/local/lib/python2.7/site-packages/flask/app.py", line 1612, in full_dispatch_request
    rv = self.dispatch_request()
  File "/usr/local/lib/python2.7/site-packages/flask/app.py", line 1598, in dispatch_request
    return self.view_functions[rule.endpoint](**req.view_args)
  File "/usr/local/lib/python2.7/site-packages/psiturk/experiment.py", line 731, in regularpage
    return render_template(pagename)
  File "/usr/local/lib/python2.7/site-packages/flask/templating.py", line 133, in render_template
    return _render(ctx.app.jinja_env.get_or_select_template(template_name_or_list),
  File "/usr/local/lib/python2.7/site-packages/jinja2/environment.py", line 869, in get_or_select_template
    return self.get_template(template_name_or_list, parent, globals)
  File "/usr/local/lib/python2.7/site-packages/jinja2/environment.py", line 830, in get_template
    return self._load_template(name, self.make_globals(globals))
  File "/usr/local/lib/python2.7/site-packages/jinja2/environment.py", line 804, in _load_template
    template = self.loader.load(self, name, globals)
  File "/usr/local/lib/python2.7/site-packages/jinja2/loaders.py", line 113, in load
    source, filename, uptodate = self.get_source(environment, name)
  File "/usr/local/lib/python2.7/site-packages/flask/templating.py", line 57, in get_source
    return self._get_source_fast(environment, template)
  File "/usr/local/lib/python2.7/site-packages/flask/templating.py", line 85, in _get_source_fast
    raise TemplateNotFound(template)
TemplateNotFound: undefined
[2019-04-20 14:38:00,098] ERROR in app: Exception on /undefined [GET]
Traceback (most recent call last):
  File "/usr/local/lib/python2.7/site-packages/flask/app.py", line 1982, in wsgi_app
    response = self.full_dispatch_request()
  File "/usr/local/lib/python2.7/site-packages/flask/app.py", line 1614, in full_dispatch_request
    rv = self.handle_user_exception(e)
  File "/usr/local/lib/python2.7/site-packages/flask/app.py", line 1517, in handle_user_exception
    reraise(exc_type, exc_value, tb)
  File "/usr/local/lib/python2.7/site-packages/flask/app.py", line 1612, in full_dispatch_request
    rv = self.dispatch_request()
  File "/usr/local/lib/python2.7/site-packages/flask/app.py", line 1598, in dispatch_request
    return self.view_functions[rule.endpoint](**req.view_args)
  File "/usr/local/lib/python2.7/site-packages/psiturk/experiment.py", line 731, in regularpage
    return render_template(pagename)
  File "/usr/local/lib/python2.7/site-packages/flask/templating.py", line 133, in render_template
    return _render(ctx.app.jinja_env.get_or_select_template(template_name_or_list),
  File "/usr/local/lib/python2.7/site-packages/jinja2/environment.py", line 869, in get_or_select_template
    return self.get_template(template_name_or_list, parent, globals)
  File "/usr/local/lib/python2.7/site-packages/jinja2/environment.py", line 830, in get_template
    return self._load_template(name, self.make_globals(globals))
  File "/usr/local/lib/python2.7/site-packages/jinja2/environment.py", line 804, in _load_template
    template = self.loader.load(self, name, globals)
  File "/usr/local/lib/python2.7/site-packages/jinja2/loaders.py", line 113, in load
    source, filename, uptodate = self.get_source(environment, name)
  File "/usr/local/lib/python2.7/site-packages/flask/templating.py", line 57, in get_source
    return self._get_source_fast(environment, template)
  File "/usr/local/lib/python2.7/site-packages/flask/templating.py", line 85, in _get_source_fast
    raise TemplateNotFound(template)
TemplateNotFound: undefined
[2019-04-20 14:38:37,475] ERROR in app: Exception on /undefined [GET]
Traceback (most recent call last):
  File "/usr/local/lib/python2.7/site-packages/flask/app.py", line 1982, in wsgi_app
    response = self.full_dispatch_request()
  File "/usr/local/lib/python2.7/site-packages/flask/app.py", line 1614, in full_dispatch_request
    rv = self.handle_user_exception(e)
  File "/usr/local/lib/python2.7/site-packages/flask/app.py", line 1517, in handle_user_exception
    reraise(exc_type, exc_value, tb)
  File "/usr/local/lib/python2.7/site-packages/flask/app.py", line 1612, in full_dispatch_request
    rv = self.dispatch_request()
  File "/usr/local/lib/python2.7/site-packages/flask/app.py", line 1598, in dispatch_request
    return self.view_functions[rule.endpoint](**req.view_args)
  File "/usr/local/lib/python2.7/site-packages/psiturk/experiment.py", line 731, in regularpage
    return render_template(pagename)
  File "/usr/local/lib/python2.7/site-packages/flask/templating.py", line 133, in render_template
    return _render(ctx.app.jinja_env.get_or_select_template(template_name_or_list),
  File "/usr/local/lib/python2.7/site-packages/jinja2/environment.py", line 869, in get_or_select_template
    return self.get_template(template_name_or_list, parent, globals)
  File "/usr/local/lib/python2.7/site-packages/jinja2/environment.py", line 830, in get_template
    return self._load_template(name, self.make_globals(globals))
  File "/usr/local/lib/python2.7/site-packages/jinja2/environment.py", line 804, in _load_template
    template = self.loader.load(self, name, globals)
  File "/usr/local/lib/python2.7/site-packages/jinja2/loaders.py", line 113, in load
    source, filename, uptodate = self.get_source(environment, name)
  File "/usr/local/lib/python2.7/site-packages/flask/templating.py", line 57, in get_source
    return self._get_source_fast(environment, template)
  File "/usr/local/lib/python2.7/site-packages/flask/templating.py", line 85, in _get_source_fast
    raise TemplateNotFound(template)
TemplateNotFound: undefined
[2019-04-20 14:39:16,327] ERROR in app: Exception on /undefined [GET]
Traceback (most recent call last):
  File "/usr/local/lib/python2.7/site-packages/flask/app.py", line 1982, in wsgi_app
    response = self.full_dispatch_request()
  File "/usr/local/lib/python2.7/site-packages/flask/app.py", line 1614, in full_dispatch_request
    rv = self.handle_user_exception(e)
  File "/usr/local/lib/python2.7/site-packages/flask/app.py", line 1517, in handle_user_exception
    reraise(exc_type, exc_value, tb)
  File "/usr/local/lib/python2.7/site-packages/flask/app.py", line 1612, in full_dispatch_request
    rv = self.dispatch_request()
  File "/usr/local/lib/python2.7/site-packages/flask/app.py", line 1598, in dispatch_request
    return self.view_functions[rule.endpoint](**req.view_args)
  File "/usr/local/lib/python2.7/site-packages/psiturk/experiment.py", line 731, in regularpage
    return render_template(pagename)
  File "/usr/local/lib/python2.7/site-packages/flask/templating.py", line 133, in render_template
    return _render(ctx.app.jinja_env.get_or_select_template(template_name_or_list),
  File "/usr/local/lib/python2.7/site-packages/jinja2/environment.py", line 869, in get_or_select_template
    return self.get_template(template_name_or_list, parent, globals)
  File "/usr/local/lib/python2.7/site-packages/jinja2/environment.py", line 830, in get_template
    return self._load_template(name, self.make_globals(globals))
  File "/usr/local/lib/python2.7/site-packages/jinja2/environment.py", line 804, in _load_template
    template = self.loader.load(self, name, globals)
  File "/usr/local/lib/python2.7/site-packages/jinja2/loaders.py", line 113, in load
    source, filename, uptodate = self.get_source(environment, name)
  File "/usr/local/lib/python2.7/site-packages/flask/templating.py", line 57, in get_source
    return self._get_source_fast(environment, template)
  File "/usr/local/lib/python2.7/site-packages/flask/templating.py", line 85, in _get_source_fast
    raise TemplateNotFound(template)
TemplateNotFound: undefined
[2019-04-20 14:40:19,653] ERROR in app: Exception on /undefined [GET]
Traceback (most recent call last):
  File "/usr/local/lib/python2.7/site-packages/flask/app.py", line 1982, in wsgi_app
    response = self.full_dispatch_request()
  File "/usr/local/lib/python2.7/site-packages/flask/app.py", line 1614, in full_dispatch_request
    rv = self.handle_user_exception(e)
  File "/usr/local/lib/python2.7/site-packages/flask/app.py", line 1517, in handle_user_exception
    reraise(exc_type, exc_value, tb)
  File "/usr/local/lib/python2.7/site-packages/flask/app.py", line 1612, in full_dispatch_request
    rv = self.dispatch_request()
  File "/usr/local/lib/python2.7/site-packages/flask/app.py", line 1598, in dispatch_request
    return self.view_functions[rule.endpoint](**req.view_args)
  File "/usr/local/lib/python2.7/site-packages/psiturk/experiment.py", line 731, in regularpage
    return render_template(pagename)
  File "/usr/local/lib/python2.7/site-packages/flask/templating.py", line 133, in render_template
    return _render(ctx.app.jinja_env.get_or_select_template(template_name_or_list),
  File "/usr/local/lib/python2.7/site-packages/jinja2/environment.py", line 869, in get_or_select_template
    return self.get_template(template_name_or_list, parent, globals)
  File "/usr/local/lib/python2.7/site-packages/jinja2/environment.py", line 830, in get_template
    return self._load_template(name, self.make_globals(globals))
  File "/usr/local/lib/python2.7/site-packages/jinja2/environment.py", line 804, in _load_template
    template = self.loader.load(self, name, globals)
  File "/usr/local/lib/python2.7/site-packages/jinja2/loaders.py", line 113, in load
    source, filename, uptodate = self.get_source(environment, name)
  File "/usr/local/lib/python2.7/site-packages/flask/templating.py", line 57, in get_source
    return self._get_source_fast(environment, template)
  File "/usr/local/lib/python2.7/site-packages/flask/templating.py", line 85, in _get_source_fast
    raise TemplateNotFound(template)
TemplateNotFound: undefined
[2019-04-20 14:40:40,458] ERROR in app: Exception on /undefined [GET]
Traceback (most recent call last):
  File "/usr/local/lib/python2.7/site-packages/flask/app.py", line 1982, in wsgi_app
    response = self.full_dispatch_request()
  File "/usr/local/lib/python2.7/site-packages/flask/app.py", line 1614, in full_dispatch_request
    rv = self.handle_user_exception(e)
  File "/usr/local/lib/python2.7/site-packages/flask/app.py", line 1517, in handle_user_exception
    reraise(exc_type, exc_value, tb)
  File "/usr/local/lib/python2.7/site-packages/flask/app.py", line 1612, in full_dispatch_request
    rv = self.dispatch_request()
  File "/usr/local/lib/python2.7/site-packages/flask/app.py", line 1598, in dispatch_request
    return self.view_functions[rule.endpoint](**req.view_args)
  File "/usr/local/lib/python2.7/site-packages/psiturk/experiment.py", line 731, in regularpage
    return render_template(pagename)
  File "/usr/local/lib/python2.7/site-packages/flask/templating.py", line 133, in render_template
    return _render(ctx.app.jinja_env.get_or_select_template(template_name_or_list),
  File "/usr/local/lib/python2.7/site-packages/jinja2/environment.py", line 869, in get_or_select_template
    return self.get_template(template_name_or_list, parent, globals)
  File "/usr/local/lib/python2.7/site-packages/jinja2/environment.py", line 830, in get_template
    return self._load_template(name, self.make_globals(globals))
  File "/usr/local/lib/python2.7/site-packages/jinja2/environment.py", line 804, in _load_template
    template = self.loader.load(self, name, globals)
  File "/usr/local/lib/python2.7/site-packages/jinja2/loaders.py", line 113, in load
    source, filename, uptodate = self.get_source(environment, name)
  File "/usr/local/lib/python2.7/site-packages/flask/templating.py", line 57, in get_source
    return self._get_source_fast(environment, template)
  File "/usr/local/lib/python2.7/site-packages/flask/templating.py", line 85, in _get_source_fast
    raise TemplateNotFound(template)
TemplateNotFound: undefined
[2019-04-20 14:42:35,649] ERROR in app: Exception on /undefined [GET]
Traceback (most recent call last):
  File "/usr/local/lib/python2.7/site-packages/flask/app.py", line 1982, in wsgi_app
    response = self.full_dispatch_request()
  File "/usr/local/lib/python2.7/site-packages/flask/app.py", line 1614, in full_dispatch_request
    rv = self.handle_user_exception(e)
  File "/usr/local/lib/python2.7/site-packages/flask/app.py", line 1517, in handle_user_exception
    reraise(exc_type, exc_value, tb)
  File "/usr/local/lib/python2.7/site-packages/flask/app.py", line 1612, in full_dispatch_request
    rv = self.dispatch_request()
  File "/usr/local/lib/python2.7/site-packages/flask/app.py", line 1598, in dispatch_request
    return self.view_functions[rule.endpoint](**req.view_args)
  File "/usr/local/lib/python2.7/site-packages/psiturk/experiment.py", line 731, in regularpage
    return render_template(pagename)
  File "/usr/local/lib/python2.7/site-packages/flask/templating.py", line 133, in render_template
    return _render(ctx.app.jinja_env.get_or_select_template(template_name_or_list),
  File "/usr/local/lib/python2.7/site-packages/jinja2/environment.py", line 869, in get_or_select_template
    return self.get_template(template_name_or_list, parent, globals)
  File "/usr/local/lib/python2.7/site-packages/jinja2/environment.py", line 830, in get_template
    return self._load_template(name, self.make_globals(globals))
  File "/usr/local/lib/python2.7/site-packages/jinja2/environment.py", line 804, in _load_template
    template = self.loader.load(self, name, globals)
  File "/usr/local/lib/python2.7/site-packages/jinja2/loaders.py", line 113, in load
    source, filename, uptodate = self.get_source(environment, name)
  File "/usr/local/lib/python2.7/site-packages/flask/templating.py", line 57, in get_source
    return self._get_source_fast(environment, template)
  File "/usr/local/lib/python2.7/site-packages/flask/templating.py", line 85, in _get_source_fast
    raise TemplateNotFound(template)
TemplateNotFound: undefined
[2019-04-20 14:43:33,745] ERROR in app: Exception on /undefined [GET]
Traceback (most recent call last):
  File "/usr/local/lib/python2.7/site-packages/flask/app.py", line 1982, in wsgi_app
    response = self.full_dispatch_request()
  File "/usr/local/lib/python2.7/site-packages/flask/app.py", line 1614, in full_dispatch_request
    rv = self.handle_user_exception(e)
  File "/usr/local/lib/python2.7/site-packages/flask/app.py", line 1517, in handle_user_exception
    reraise(exc_type, exc_value, tb)
  File "/usr/local/lib/python2.7/site-packages/flask/app.py", line 1612, in full_dispatch_request
    rv = self.dispatch_request()
  File "/usr/local/lib/python2.7/site-packages/flask/app.py", line 1598, in dispatch_request
    return self.view_functions[rule.endpoint](**req.view_args)
  File "/usr/local/lib/python2.7/site-packages/psiturk/experiment.py", line 731, in regularpage
    return render_template(pagename)
  File "/usr/local/lib/python2.7/site-packages/flask/templating.py", line 133, in render_template
    return _render(ctx.app.jinja_env.get_or_select_template(template_name_or_list),
  File "/usr/local/lib/python2.7/site-packages/jinja2/environment.py", line 869, in get_or_select_template
    return self.get_template(template_name_or_list, parent, globals)
  File "/usr/local/lib/python2.7/site-packages/jinja2/environment.py", line 830, in get_template
    return self._load_template(name, self.make_globals(globals))
  File "/usr/local/lib/python2.7/site-packages/jinja2/environment.py", line 804, in _load_template
    template = self.loader.load(self, name, globals)
  File "/usr/local/lib/python2.7/site-packages/jinja2/loaders.py", line 113, in load
    source, filename, uptodate = self.get_source(environment, name)
  File "/usr/local/lib/python2.7/site-packages/flask/templating.py", line 57, in get_source
    return self._get_source_fast(environment, template)
  File "/usr/local/lib/python2.7/site-packages/flask/templating.py", line 85, in _get_source_fast
    raise TemplateNotFound(template)
TemplateNotFound: undefined
[2019-04-20 14:43:35,938] ERROR in app: Exception on /undefined [GET]
Traceback (most recent call last):
  File "/usr/local/lib/python2.7/site-packages/flask/app.py", line 1982, in wsgi_app
    response = self.full_dispatch_request()
  File "/usr/local/lib/python2.7/site-packages/flask/app.py", line 1614, in full_dispatch_request
    rv = self.handle_user_exception(e)
  File "/usr/local/lib/python2.7/site-packages/flask/app.py", line 1517, in handle_user_exception
    reraise(exc_type, exc_value, tb)
  File "/usr/local/lib/python2.7/site-packages/flask/app.py", line 1612, in full_dispatch_request
    rv = self.dispatch_request()
  File "/usr/local/lib/python2.7/site-packages/flask/app.py", line 1598, in dispatch_request
    return self.view_functions[rule.endpoint](**req.view_args)
  File "/usr/local/lib/python2.7/site-packages/psiturk/experiment.py", line 731, in regularpage
    return render_template(pagename)
  File "/usr/local/lib/python2.7/site-packages/flask/templating.py", line 133, in render_template
    return _render(ctx.app.jinja_env.get_or_select_template(template_name_or_list),
  File "/usr/local/lib/python2.7/site-packages/jinja2/environment.py", line 869, in get_or_select_template
    return self.get_template(template_name_or_list, parent, globals)
  File "/usr/local/lib/python2.7/site-packages/jinja2/environment.py", line 830, in get_template
    return self._load_template(name, self.make_globals(globals))
  File "/usr/local/lib/python2.7/site-packages/jinja2/environment.py", line 804, in _load_template
    template = self.loader.load(self, name, globals)
  File "/usr/local/lib/python2.7/site-packages/jinja2/loaders.py", line 113, in load
    source, filename, uptodate = self.get_source(environment, name)
  File "/usr/local/lib/python2.7/site-packages/flask/templating.py", line 57, in get_source
    return self._get_source_fast(environment, template)
  File "/usr/local/lib/python2.7/site-packages/flask/templating.py", line 85, in _get_source_fast
    raise TemplateNotFound(template)
TemplateNotFound: undefined
[2019-04-20 14:45:33,391] ERROR in app: Exception on /undefined [GET]
Traceback (most recent call last):
  File "/usr/local/lib/python2.7/site-packages/flask/app.py", line 1982, in wsgi_app
    response = self.full_dispatch_request()
  File "/usr/local/lib/python2.7/site-packages/flask/app.py", line 1614, in full_dispatch_request
    rv = self.handle_user_exception(e)
  File "/usr/local/lib/python2.7/site-packages/flask/app.py", line 1517, in handle_user_exception
    reraise(exc_type, exc_value, tb)
  File "/usr/local/lib/python2.7/site-packages/flask/app.py", line 1612, in full_dispatch_request
    rv = self.dispatch_request()
  File "/usr/local/lib/python2.7/site-packages/flask/app.py", line 1598, in dispatch_request
    return self.view_functions[rule.endpoint](**req.view_args)
  File "/usr/local/lib/python2.7/site-packages/psiturk/experiment.py", line 731, in regularpage
    return render_template(pagename)
  File "/usr/local/lib/python2.7/site-packages/flask/templating.py", line 133, in render_template
    return _render(ctx.app.jinja_env.get_or_select_template(template_name_or_list),
  File "/usr/local/lib/python2.7/site-packages/jinja2/environment.py", line 869, in get_or_select_template
    return self.get_template(template_name_or_list, parent, globals)
  File "/usr/local/lib/python2.7/site-packages/jinja2/environment.py", line 830, in get_template
    return self._load_template(name, self.make_globals(globals))
  File "/usr/local/lib/python2.7/site-packages/jinja2/environment.py", line 804, in _load_template
    template = self.loader.load(self, name, globals)
  File "/usr/local/lib/python2.7/site-packages/jinja2/loaders.py", line 113, in load
    source, filename, uptodate = self.get_source(environment, name)
  File "/usr/local/lib/python2.7/site-packages/flask/templating.py", line 57, in get_source
    return self._get_source_fast(environment, template)
  File "/usr/local/lib/python2.7/site-packages/flask/templating.py", line 85, in _get_source_fast
    raise TemplateNotFound(template)
TemplateNotFound: undefined
[2019-04-20 14:47:10,797] ERROR in app: Exception on /undefined [GET]
Traceback (most recent call last):
  File "/usr/local/lib/python2.7/site-packages/flask/app.py", line 1982, in wsgi_app
    response = self.full_dispatch_request()
  File "/usr/local/lib/python2.7/site-packages/flask/app.py", line 1614, in full_dispatch_request
    rv = self.handle_user_exception(e)
  File "/usr/local/lib/python2.7/site-packages/flask/app.py", line 1517, in handle_user_exception
    reraise(exc_type, exc_value, tb)
  File "/usr/local/lib/python2.7/site-packages/flask/app.py", line 1612, in full_dispatch_request
    rv = self.dispatch_request()
  File "/usr/local/lib/python2.7/site-packages/flask/app.py", line 1598, in dispatch_request
    return self.view_functions[rule.endpoint](**req.view_args)
  File "/usr/local/lib/python2.7/site-packages/psiturk/experiment.py", line 731, in regularpage
    return render_template(pagename)
  File "/usr/local/lib/python2.7/site-packages/flask/templating.py", line 133, in render_template
    return _render(ctx.app.jinja_env.get_or_select_template(template_name_or_list),
  File "/usr/local/lib/python2.7/site-packages/jinja2/environment.py", line 869, in get_or_select_template
    return self.get_template(template_name_or_list, parent, globals)
  File "/usr/local/lib/python2.7/site-packages/jinja2/environment.py", line 830, in get_template
    return self._load_template(name, self.make_globals(globals))
  File "/usr/local/lib/python2.7/site-packages/jinja2/environment.py", line 804, in _load_template
    template = self.loader.load(self, name, globals)
  File "/usr/local/lib/python2.7/site-packages/jinja2/loaders.py", line 113, in load
    source, filename, uptodate = self.get_source(environment, name)
  File "/usr/local/lib/python2.7/site-packages/flask/templating.py", line 57, in get_source
    return self._get_source_fast(environment, template)
  File "/usr/local/lib/python2.7/site-packages/flask/templating.py", line 85, in _get_source_fast
    raise TemplateNotFound(template)
TemplateNotFound: undefined
[2019-04-20 14:52:56,427] ERROR in app: Exception on /undefined [GET]
Traceback (most recent call last):
  File "/usr/local/lib/python2.7/site-packages/flask/app.py", line 1982, in wsgi_app
    response = self.full_dispatch_request()
  File "/usr/local/lib/python2.7/site-packages/flask/app.py", line 1614, in full_dispatch_request
    rv = self.handle_user_exception(e)
  File "/usr/local/lib/python2.7/site-packages/flask/app.py", line 1517, in handle_user_exception
    reraise(exc_type, exc_value, tb)
  File "/usr/local/lib/python2.7/site-packages/flask/app.py", line 1612, in full_dispatch_request
    rv = self.dispatch_request()
  File "/usr/local/lib/python2.7/site-packages/flask/app.py", line 1598, in dispatch_request
    return self.view_functions[rule.endpoint](**req.view_args)
  File "/usr/local/lib/python2.7/site-packages/psiturk/experiment.py", line 731, in regularpage
    return render_template(pagename)
  File "/usr/local/lib/python2.7/site-packages/flask/templating.py", line 133, in render_template
    return _render(ctx.app.jinja_env.get_or_select_template(template_name_or_list),
  File "/usr/local/lib/python2.7/site-packages/jinja2/environment.py", line 869, in get_or_select_template
    return self.get_template(template_name_or_list, parent, globals)
  File "/usr/local/lib/python2.7/site-packages/jinja2/environment.py", line 830, in get_template
    return self._load_template(name, self.make_globals(globals))
  File "/usr/local/lib/python2.7/site-packages/jinja2/environment.py", line 804, in _load_template
    template = self.loader.load(self, name, globals)
  File "/usr/local/lib/python2.7/site-packages/jinja2/loaders.py", line 113, in load
    source, filename, uptodate = self.get_source(environment, name)
  File "/usr/local/lib/python2.7/site-packages/flask/templating.py", line 57, in get_source
    return self._get_source_fast(environment, template)
  File "/usr/local/lib/python2.7/site-packages/flask/templating.py", line 85, in _get_source_fast
    raise TemplateNotFound(template)
TemplateNotFound: undefined
[2019-04-20 14:54:00,093] ERROR in app: Exception on /undefined [GET]
Traceback (most recent call last):
  File "/usr/local/lib/python2.7/site-packages/flask/app.py", line 1982, in wsgi_app
    response = self.full_dispatch_request()
  File "/usr/local/lib/python2.7/site-packages/flask/app.py", line 1614, in full_dispatch_request
    rv = self.handle_user_exception(e)
  File "/usr/local/lib/python2.7/site-packages/flask/app.py", line 1517, in handle_user_exception
    reraise(exc_type, exc_value, tb)
  File "/usr/local/lib/python2.7/site-packages/flask/app.py", line 1612, in full_dispatch_request
    rv = self.dispatch_request()
  File "/usr/local/lib/python2.7/site-packages/flask/app.py", line 1598, in dispatch_request
    return self.view_functions[rule.endpoint](**req.view_args)
  File "/usr/local/lib/python2.7/site-packages/psiturk/experiment.py", line 731, in regularpage
    return render_template(pagename)
  File "/usr/local/lib/python2.7/site-packages/flask/templating.py", line 133, in render_template
    return _render(ctx.app.jinja_env.get_or_select_template(template_name_or_list),
  File "/usr/local/lib/python2.7/site-packages/jinja2/environment.py", line 869, in get_or_select_template
    return self.get_template(template_name_or_list, parent, globals)
  File "/usr/local/lib/python2.7/site-packages/jinja2/environment.py", line 830, in get_template
    return self._load_template(name, self.make_globals(globals))
  File "/usr/local/lib/python2.7/site-packages/jinja2/environment.py", line 804, in _load_template
    template = self.loader.load(self, name, globals)
  File "/usr/local/lib/python2.7/site-packages/jinja2/loaders.py", line 113, in load
    source, filename, uptodate = self.get_source(environment, name)
  File "/usr/local/lib/python2.7/site-packages/flask/templating.py", line 57, in get_source
    return self._get_source_fast(environment, template)
  File "/usr/local/lib/python2.7/site-packages/flask/templating.py", line 85, in _get_source_fast
    raise TemplateNotFound(template)
TemplateNotFound: undefined
[2019-04-20 14:59:57,999] ERROR in app: Exception on /undefined [GET]
Traceback (most recent call last):
  File "/usr/local/lib/python2.7/site-packages/flask/app.py", line 1982, in wsgi_app
    response = self.full_dispatch_request()
  File "/usr/local/lib/python2.7/site-packages/flask/app.py", line 1614, in full_dispatch_request
    rv = self.handle_user_exception(e)
  File "/usr/local/lib/python2.7/site-packages/flask/app.py", line 1517, in handle_user_exception
    reraise(exc_type, exc_value, tb)
  File "/usr/local/lib/python2.7/site-packages/flask/app.py", line 1612, in full_dispatch_request
    rv = self.dispatch_request()
  File "/usr/local/lib/python2.7/site-packages/flask/app.py", line 1598, in dispatch_request
    return self.view_functions[rule.endpoint](**req.view_args)
  File "/usr/local/lib/python2.7/site-packages/psiturk/experiment.py", line 731, in regularpage
    return render_template(pagename)
  File "/usr/local/lib/python2.7/site-packages/flask/templating.py", line 133, in render_template
    return _render(ctx.app.jinja_env.get_or_select_template(template_name_or_list),
  File "/usr/local/lib/python2.7/site-packages/jinja2/environment.py", line 869, in get_or_select_template
    return self.get_template(template_name_or_list, parent, globals)
  File "/usr/local/lib/python2.7/site-packages/jinja2/environment.py", line 830, in get_template
    return self._load_template(name, self.make_globals(globals))
  File "/usr/local/lib/python2.7/site-packages/jinja2/environment.py", line 804, in _load_template
    template = self.loader.load(self, name, globals)
  File "/usr/local/lib/python2.7/site-packages/jinja2/loaders.py", line 113, in load
    source, filename, uptodate = self.get_source(environment, name)
  File "/usr/local/lib/python2.7/site-packages/flask/templating.py", line 57, in get_source
    return self._get_source_fast(environment, template)
  File "/usr/local/lib/python2.7/site-packages/flask/templating.py", line 85, in _get_source_fast
    raise TemplateNotFound(template)
TemplateNotFound: undefined
[2019-04-20 15:02:28,179] ERROR in app: Exception on /undefined [GET]
Traceback (most recent call last):
  File "/usr/local/lib/python2.7/site-packages/flask/app.py", line 1982, in wsgi_app
    response = self.full_dispatch_request()
  File "/usr/local/lib/python2.7/site-packages/flask/app.py", line 1614, in full_dispatch_request
    rv = self.handle_user_exception(e)
  File "/usr/local/lib/python2.7/site-packages/flask/app.py", line 1517, in handle_user_exception
    reraise(exc_type, exc_value, tb)
  File "/usr/local/lib/python2.7/site-packages/flask/app.py", line 1612, in full_dispatch_request
    rv = self.dispatch_request()
  File "/usr/local/lib/python2.7/site-packages/flask/app.py", line 1598, in dispatch_request
    return self.view_functions[rule.endpoint](**req.view_args)
  File "/usr/local/lib/python2.7/site-packages/psiturk/experiment.py", line 731, in regularpage
    return render_template(pagename)
  File "/usr/local/lib/python2.7/site-packages/flask/templating.py", line 133, in render_template
    return _render(ctx.app.jinja_env.get_or_select_template(template_name_or_list),
  File "/usr/local/lib/python2.7/site-packages/jinja2/environment.py", line 869, in get_or_select_template
    return self.get_template(template_name_or_list, parent, globals)
  File "/usr/local/lib/python2.7/site-packages/jinja2/environment.py", line 830, in get_template
    return self._load_template(name, self.make_globals(globals))
  File "/usr/local/lib/python2.7/site-packages/jinja2/environment.py", line 804, in _load_template
    template = self.loader.load(self, name, globals)
  File "/usr/local/lib/python2.7/site-packages/jinja2/loaders.py", line 113, in load
    source, filename, uptodate = self.get_source(environment, name)
  File "/usr/local/lib/python2.7/site-packages/flask/templating.py", line 57, in get_source
    return self._get_source_fast(environment, template)
  File "/usr/local/lib/python2.7/site-packages/flask/templating.py", line 85, in _get_source_fast
    raise TemplateNotFound(template)
TemplateNotFound: undefined
[2019-04-20 15:03:48,815] ERROR in app: Exception on /undefined [GET]
Traceback (most recent call last):
  File "/usr/local/lib/python2.7/site-packages/flask/app.py", line 1982, in wsgi_app
    response = self.full_dispatch_request()
  File "/usr/local/lib/python2.7/site-packages/flask/app.py", line 1614, in full_dispatch_request
    rv = self.handle_user_exception(e)
  File "/usr/local/lib/python2.7/site-packages/flask/app.py", line 1517, in handle_user_exception
    reraise(exc_type, exc_value, tb)
  File "/usr/local/lib/python2.7/site-packages/flask/app.py", line 1612, in full_dispatch_request
    rv = self.dispatch_request()
  File "/usr/local/lib/python2.7/site-packages/flask/app.py", line 1598, in dispatch_request
    return self.view_functions[rule.endpoint](**req.view_args)
  File "/usr/local/lib/python2.7/site-packages/psiturk/experiment.py", line 731, in regularpage
    return render_template(pagename)
  File "/usr/local/lib/python2.7/site-packages/flask/templating.py", line 133, in render_template
    return _render(ctx.app.jinja_env.get_or_select_template(template_name_or_list),
  File "/usr/local/lib/python2.7/site-packages/jinja2/environment.py", line 869, in get_or_select_template
    return self.get_template(template_name_or_list, parent, globals)
  File "/usr/local/lib/python2.7/site-packages/jinja2/environment.py", line 830, in get_template
    return self._load_template(name, self.make_globals(globals))
  File "/usr/local/lib/python2.7/site-packages/jinja2/environment.py", line 804, in _load_template
    template = self.loader.load(self, name, globals)
  File "/usr/local/lib/python2.7/site-packages/jinja2/loaders.py", line 113, in load
    source, filename, uptodate = self.get_source(environment, name)
  File "/usr/local/lib/python2.7/site-packages/flask/templating.py", line 57, in get_source
    return self._get_source_fast(environment, template)
  File "/usr/local/lib/python2.7/site-packages/flask/templating.py", line 85, in _get_source_fast
    raise TemplateNotFound(template)
TemplateNotFound: undefined
[2019-04-20 15:05:34,436] ERROR in app: Exception on /undefined [GET]
Traceback (most recent call last):
  File "/usr/local/lib/python2.7/site-packages/flask/app.py", line 1982, in wsgi_app
    response = self.full_dispatch_request()
  File "/usr/local/lib/python2.7/site-packages/flask/app.py", line 1614, in full_dispatch_request
    rv = self.handle_user_exception(e)
  File "/usr/local/lib/python2.7/site-packages/flask/app.py", line 1517, in handle_user_exception
    reraise(exc_type, exc_value, tb)
  File "/usr/local/lib/python2.7/site-packages/flask/app.py", line 1612, in full_dispatch_request
    rv = self.dispatch_request()
  File "/usr/local/lib/python2.7/site-packages/flask/app.py", line 1598, in dispatch_request
    return self.view_functions[rule.endpoint](**req.view_args)
  File "/usr/local/lib/python2.7/site-packages/psiturk/experiment.py", line 731, in regularpage
    return render_template(pagename)
  File "/usr/local/lib/python2.7/site-packages/flask/templating.py", line 133, in render_template
    return _render(ctx.app.jinja_env.get_or_select_template(template_name_or_list),
  File "/usr/local/lib/python2.7/site-packages/jinja2/environment.py", line 869, in get_or_select_template
    return self.get_template(template_name_or_list, parent, globals)
  File "/usr/local/lib/python2.7/site-packages/jinja2/environment.py", line 830, in get_template
    return self._load_template(name, self.make_globals(globals))
  File "/usr/local/lib/python2.7/site-packages/jinja2/environment.py", line 804, in _load_template
    template = self.loader.load(self, name, globals)
  File "/usr/local/lib/python2.7/site-packages/jinja2/loaders.py", line 113, in load
    source, filename, uptodate = self.get_source(environment, name)
  File "/usr/local/lib/python2.7/site-packages/flask/templating.py", line 57, in get_source
    return self._get_source_fast(environment, template)
  File "/usr/local/lib/python2.7/site-packages/flask/templating.py", line 85, in _get_source_fast
    raise TemplateNotFound(template)
TemplateNotFound: undefined
[2019-04-20 15:08:06,703] ERROR in app: Exception on /undefined [GET]
Traceback (most recent call last):
  File "/usr/local/lib/python2.7/site-packages/flask/app.py", line 1982, in wsgi_app
    response = self.full_dispatch_request()
  File "/usr/local/lib/python2.7/site-packages/flask/app.py", line 1614, in full_dispatch_request
    rv = self.handle_user_exception(e)
  File "/usr/local/lib/python2.7/site-packages/flask/app.py", line 1517, in handle_user_exception
    reraise(exc_type, exc_value, tb)
  File "/usr/local/lib/python2.7/site-packages/flask/app.py", line 1612, in full_dispatch_request
    rv = self.dispatch_request()
  File "/usr/local/lib/python2.7/site-packages/flask/app.py", line 1598, in dispatch_request
    return self.view_functions[rule.endpoint](**req.view_args)
  File "/usr/local/lib/python2.7/site-packages/psiturk/experiment.py", line 731, in regularpage
    return render_template(pagename)
  File "/usr/local/lib/python2.7/site-packages/flask/templating.py", line 133, in render_template
    return _render(ctx.app.jinja_env.get_or_select_template(template_name_or_list),
  File "/usr/local/lib/python2.7/site-packages/jinja2/environment.py", line 869, in get_or_select_template
    return self.get_template(template_name_or_list, parent, globals)
  File "/usr/local/lib/python2.7/site-packages/jinja2/environment.py", line 830, in get_template
    return self._load_template(name, self.make_globals(globals))
  File "/usr/local/lib/python2.7/site-packages/jinja2/environment.py", line 804, in _load_template
    template = self.loader.load(self, name, globals)
  File "/usr/local/lib/python2.7/site-packages/jinja2/loaders.py", line 113, in load
    source, filename, uptodate = self.get_source(environment, name)
  File "/usr/local/lib/python2.7/site-packages/flask/templating.py", line 57, in get_source
    return self._get_source_fast(environment, template)
  File "/usr/local/lib/python2.7/site-packages/flask/templating.py", line 85, in _get_source_fast
    raise TemplateNotFound(template)
TemplateNotFound: undefined
[2019-04-20 15:16:26,140] ERROR in app: Exception on /tor.wager@colorado.edu [GET]
Traceback (most recent call last):
  File "/usr/local/lib/python2.7/site-packages/flask/app.py", line 1982, in wsgi_app
    response = self.full_dispatch_request()
  File "/usr/local/lib/python2.7/site-packages/flask/app.py", line 1614, in full_dispatch_request
    rv = self.handle_user_exception(e)
  File "/usr/local/lib/python2.7/site-packages/flask/app.py", line 1517, in handle_user_exception
    reraise(exc_type, exc_value, tb)
  File "/usr/local/lib/python2.7/site-packages/flask/app.py", line 1612, in full_dispatch_request
    rv = self.dispatch_request()
  File "/usr/local/lib/python2.7/site-packages/flask/app.py", line 1598, in dispatch_request
    return self.view_functions[rule.endpoint](**req.view_args)
  File "/usr/local/lib/python2.7/site-packages/psiturk/experiment.py", line 731, in regularpage
    return render_template(pagename)
  File "/usr/local/lib/python2.7/site-packages/flask/templating.py", line 133, in render_template
    return _render(ctx.app.jinja_env.get_or_select_template(template_name_or_list),
  File "/usr/local/lib/python2.7/site-packages/jinja2/environment.py", line 869, in get_or_select_template
    return self.get_template(template_name_or_list, parent, globals)
  File "/usr/local/lib/python2.7/site-packages/jinja2/environment.py", line 830, in get_template
    return self._load_template(name, self.make_globals(globals))
  File "/usr/local/lib/python2.7/site-packages/jinja2/environment.py", line 804, in _load_template
    template = self.loader.load(self, name, globals)
  File "/usr/local/lib/python2.7/site-packages/jinja2/loaders.py", line 113, in load
    source, filename, uptodate = self.get_source(environment, name)
  File "/usr/local/lib/python2.7/site-packages/flask/templating.py", line 57, in get_source
    return self._get_source_fast(environment, template)
  File "/usr/local/lib/python2.7/site-packages/flask/templating.py", line 85, in _get_source_fast
    raise TemplateNotFound(template)
TemplateNotFound: tor.wager@colorado.edu
[2019-04-20 22:35:44,918] ERROR in app: Exception on /undefined [GET]
Traceback (most recent call last):
  File "/usr/local/lib/python2.7/site-packages/flask/app.py", line 1982, in wsgi_app
    response = self.full_dispatch_request()
  File "/usr/local/lib/python2.7/site-packages/flask/app.py", line 1614, in full_dispatch_request
    rv = self.handle_user_exception(e)
  File "/usr/local/lib/python2.7/site-packages/flask/app.py", line 1517, in handle_user_exception
    reraise(exc_type, exc_value, tb)
  File "/usr/local/lib/python2.7/site-packages/flask/app.py", line 1612, in full_dispatch_request
    rv = self.dispatch_request()
  File "/usr/local/lib/python2.7/site-packages/flask/app.py", line 1598, in dispatch_request
    return self.view_functions[rule.endpoint](**req.view_args)
  File "/usr/local/lib/python2.7/site-packages/psiturk/experiment.py", line 731, in regularpage
    return render_template(pagename)
  File "/usr/local/lib/python2.7/site-packages/flask/templating.py", line 133, in render_template
    return _render(ctx.app.jinja_env.get_or_select_template(template_name_or_list),
  File "/usr/local/lib/python2.7/site-packages/jinja2/environment.py", line 869, in get_or_select_template
    return self.get_template(template_name_or_list, parent, globals)
  File "/usr/local/lib/python2.7/site-packages/jinja2/environment.py", line 830, in get_template
    return self._load_template(name, self.make_globals(globals))
  File "/usr/local/lib/python2.7/site-packages/jinja2/environment.py", line 804, in _load_template
    template = self.loader.load(self, name, globals)
  File "/usr/local/lib/python2.7/site-packages/jinja2/loaders.py", line 113, in load
    source, filename, uptodate = self.get_source(environment, name)
  File "/usr/local/lib/python2.7/site-packages/flask/templating.py", line 57, in get_source
    return self._get_source_fast(environment, template)
  File "/usr/local/lib/python2.7/site-packages/flask/templating.py", line 85, in _get_source_fast
    raise TemplateNotFound(template)
TemplateNotFound: undefined
[2019-04-20 22:37:00,313] ERROR in app: Exception on /undefined [GET]
Traceback (most recent call last):
  File "/usr/local/lib/python2.7/site-packages/flask/app.py", line 1982, in wsgi_app
    response = self.full_dispatch_request()
  File "/usr/local/lib/python2.7/site-packages/flask/app.py", line 1614, in full_dispatch_request
    rv = self.handle_user_exception(e)
  File "/usr/local/lib/python2.7/site-packages/flask/app.py", line 1517, in handle_user_exception
    reraise(exc_type, exc_value, tb)
  File "/usr/local/lib/python2.7/site-packages/flask/app.py", line 1612, in full_dispatch_request
    rv = self.dispatch_request()
  File "/usr/local/lib/python2.7/site-packages/flask/app.py", line 1598, in dispatch_request
    return self.view_functions[rule.endpoint](**req.view_args)
  File "/usr/local/lib/python2.7/site-packages/psiturk/experiment.py", line 731, in regularpage
    return render_template(pagename)
  File "/usr/local/lib/python2.7/site-packages/flask/templating.py", line 133, in render_template
    return _render(ctx.app.jinja_env.get_or_select_template(template_name_or_list),
  File "/usr/local/lib/python2.7/site-packages/jinja2/environment.py", line 869, in get_or_select_template
    return self.get_template(template_name_or_list, parent, globals)
  File "/usr/local/lib/python2.7/site-packages/jinja2/environment.py", line 830, in get_template
    return self._load_template(name, self.make_globals(globals))
  File "/usr/local/lib/python2.7/site-packages/jinja2/environment.py", line 804, in _load_template
    template = self.loader.load(self, name, globals)
  File "/usr/local/lib/python2.7/site-packages/jinja2/loaders.py", line 113, in load
    source, filename, uptodate = self.get_source(environment, name)
  File "/usr/local/lib/python2.7/site-packages/flask/templating.py", line 57, in get_source
    return self._get_source_fast(environment, template)
  File "/usr/local/lib/python2.7/site-packages/flask/templating.py", line 85, in _get_source_fast
    raise TemplateNotFound(template)
TemplateNotFound: undefined
[2019-04-20 22:38:59,541] ERROR in app: Exception on /undefined [GET]
Traceback (most recent call last):
  File "/usr/local/lib/python2.7/site-packages/flask/app.py", line 1982, in wsgi_app
    response = self.full_dispatch_request()
  File "/usr/local/lib/python2.7/site-packages/flask/app.py", line 1614, in full_dispatch_request
    rv = self.handle_user_exception(e)
  File "/usr/local/lib/python2.7/site-packages/flask/app.py", line 1517, in handle_user_exception
    reraise(exc_type, exc_value, tb)
  File "/usr/local/lib/python2.7/site-packages/flask/app.py", line 1612, in full_dispatch_request
    rv = self.dispatch_request()
  File "/usr/local/lib/python2.7/site-packages/flask/app.py", line 1598, in dispatch_request
    return self.view_functions[rule.endpoint](**req.view_args)
  File "/usr/local/lib/python2.7/site-packages/psiturk/experiment.py", line 731, in regularpage
    return render_template(pagename)
  File "/usr/local/lib/python2.7/site-packages/flask/templating.py", line 133, in render_template
    return _render(ctx.app.jinja_env.get_or_select_template(template_name_or_list),
  File "/usr/local/lib/python2.7/site-packages/jinja2/environment.py", line 869, in get_or_select_template
    return self.get_template(template_name_or_list, parent, globals)
  File "/usr/local/lib/python2.7/site-packages/jinja2/environment.py", line 830, in get_template
    return self._load_template(name, self.make_globals(globals))
  File "/usr/local/lib/python2.7/site-packages/jinja2/environment.py", line 804, in _load_template
    template = self.loader.load(self, name, globals)
  File "/usr/local/lib/python2.7/site-packages/jinja2/loaders.py", line 113, in load
    source, filename, uptodate = self.get_source(environment, name)
  File "/usr/local/lib/python2.7/site-packages/flask/templating.py", line 57, in get_source
    return self._get_source_fast(environment, template)
  File "/usr/local/lib/python2.7/site-packages/flask/templating.py", line 85, in _get_source_fast
    raise TemplateNotFound(template)
TemplateNotFound: undefined
[2019-04-20 22:39:16,539] ERROR in app: Exception on /undefined [GET]
Traceback (most recent call last):
  File "/usr/local/lib/python2.7/site-packages/flask/app.py", line 1982, in wsgi_app
    response = self.full_dispatch_request()
  File "/usr/local/lib/python2.7/site-packages/flask/app.py", line 1614, in full_dispatch_request
    rv = self.handle_user_exception(e)
  File "/usr/local/lib/python2.7/site-packages/flask/app.py", line 1517, in handle_user_exception
    reraise(exc_type, exc_value, tb)
  File "/usr/local/lib/python2.7/site-packages/flask/app.py", line 1612, in full_dispatch_request
    rv = self.dispatch_request()
  File "/usr/local/lib/python2.7/site-packages/flask/app.py", line 1598, in dispatch_request
    return self.view_functions[rule.endpoint](**req.view_args)
  File "/usr/local/lib/python2.7/site-packages/psiturk/experiment.py", line 731, in regularpage
    return render_template(pagename)
  File "/usr/local/lib/python2.7/site-packages/flask/templating.py", line 133, in render_template
    return _render(ctx.app.jinja_env.get_or_select_template(template_name_or_list),
  File "/usr/local/lib/python2.7/site-packages/jinja2/environment.py", line 869, in get_or_select_template
    return self.get_template(template_name_or_list, parent, globals)
  File "/usr/local/lib/python2.7/site-packages/jinja2/environment.py", line 830, in get_template
    return self._load_template(name, self.make_globals(globals))
  File "/usr/local/lib/python2.7/site-packages/jinja2/environment.py", line 804, in _load_template
    template = self.loader.load(self, name, globals)
  File "/usr/local/lib/python2.7/site-packages/jinja2/loaders.py", line 113, in load
    source, filename, uptodate = self.get_source(environment, name)
  File "/usr/local/lib/python2.7/site-packages/flask/templating.py", line 57, in get_source
    return self._get_source_fast(environment, template)
  File "/usr/local/lib/python2.7/site-packages/flask/templating.py", line 85, in _get_source_fast
    raise TemplateNotFound(template)
TemplateNotFound: undefined
